Workbook

Sheet Monthwise
K2: Scripting | O2: ER | R2: Production
A4: Week - Month | B4: PPV - Show_id | C4: Production Show_id | D4: Show_name | E4: Production status | F4: Writer | G4: POD lead | H4: Producer | I4: Till Date Scripts | J4: Total Duration Live | K4: Week's Target | L4: =CONCATENATE("Scripts Submitted as on ", TEXT(TODAY()-1,"dd-mmm-yyyy")) -> Scripts Submitted as on 14-May-2026 | M4: =CONCATENATE("Scripts Submitted WC as on ", TEXT(TODAY()-1,"dd-mmm-yyyy")) -> Scripts Submitted WC as on 14-May-2026 | N4: Missed By | O4: Week's Target | P4: ER Approved Scripts | Q4: Approval Pending | R4: Week's Target | S4: Live Episodes | T4: Missed By | V4: Week's Start Date
A5: W1 - May'26 | B5: dbbc7f35e9eb33b7562f0fd82896e827101bf13c | C5: b9727274f880f47671ad54caad4904a491fad9c7 | D5: Brahmand Ka Rakshak | E5: Running | F5: Trupti | G5: Vijay | I5: =IFERROR(VLOOKUP($C5,'Show Details'!A:Z,7,0),"") | K5: 18 | L5: =SUMIFS(Dump!$D:$D,Dump!$B:$B,$C5,Dump!$A:$A,$V5) -> 18 | M5: =SUMIFS(Dump!R:R,Dump!B:B,C5,Dump!A:A,V5) -> 41129 | N5: =K5-L5 -> 0 | P5: =SUMIFS(Dump!E:E,Dump!B:B,C5,Dump!A:A,V5) -> 28 | Q5: =O5-P5 -> -28 | S5: =SUMIFS(Dump!P:P,Dump!B:B,C5,Dump!A:A,V5) -> 36 | T5: =R5-S5 -> -36 | V5: 46146
A6: W1 - May'26 | B6: f43f4253dc3c596ff8f2e3cc9f3b677981a70310 | C6: 5baf4c80faf4b2d4eb9401a1d0081872e0158e89 | D6: Brahmyodha the Destroyer | E6: Running | F6: Deepaa | G6: Shivani | I6: =IFERROR(VLOOKUP($C6,'Show Details'!A:Z,7,0),"") | K6: 15 | L6: =SUMIFS(Dump!$D:$D,Dump!$B:$B,$C6,Dump!$A:$A,$V6) -> 15 | M6: =SUMIFS(Dump!R:R,Dump!B:B,C6,Dump!A:A,V6) -> 35976 | N6: =K6-L6 -> 0 | P6: =SUMIFS(Dump!E:E,Dump!B:B,C6,Dump!A:A,V6) -> 20 | Q6: =O6-P6 -> -20 | S6: =SUMIFS(Dump!P:P,Dump!B:B,C6,Dump!A:A,V6) -> 24 | T6: =R6-S6 -> -24 | V6: 46146
A7: W1 - May'26 | B7: 859785ba4869b28dddcfcb0e75295d1e1ad9b5a9 | C7: 96f1f89e4494e06fb7f9e3c4645563fa62ef9320 | D7: King of Dragon | E7: Running | F7: Deepaa | G7: Amit Rajak | I7: =IFERROR(VLOOKUP($C7,'Show Details'!A:Z,7,0),"") | K7: 12 | L7: =SUMIFS(Dump!$D:$D,Dump!$B:$B,$C7,Dump!$A:$A,$V7) -> 12 | M7: =SUMIFS(Dump!R:R,Dump!B:B,C7,Dump!A:A,V7) -> 28878 | N7: =K7-L7 -> 0 | P7: =SUMIFS(Dump!E:E,Dump!B:B,C7,Dump!A:A,V7) -> 13 | Q7: =O7-P7 -> -13 | S7: =SUMIFS(Dump!P:P,Dump!B:B,C7,Dump!A:A,V7) -> 17 | T7: =R7-S7 -> -17 | V7: 46146
A8: W1 - May'26 | B8: 641b6f77fd211e92df35a3bcbab67e6879e19a66 | C8: 773d29931b435627d0ca406e1ea1425e9a1dbcb6 | D8: Mahagatha | F8: Shivam | G8: NItesh | I8: =IFERROR(VLOOKUP($C8,'Show Details'!A:Z,7,0),"") | K8: 20 | L8: =SUMIFS(Dump!$D:$D,Dump!$B:$B,$C8,Dump!$A:$A,$V8) -> 18 | M8: =SUMIFS(Dump!R:R,Dump!B:B,C8,Dump!A:A,V8) -> 45583 | N8: =K8-L8 -> 2 | P8: =SUMIFS(Dump!E:E,Dump!B:B,C8,Dump!A:A,V8) -> 22 | Q8: =O8-P8 -> -22 | S8: =SUMIFS(Dump!P:P,Dump!B:B,C8,Dump!A:A,V8) -> 15 | T8: =R8-S8 -> -15 | V8: 46146
A9: W1 - May'26 | B9: e493cee863483a057af12de782cd20043a19ed05 | C9: 4c7fcc2bad9d3ae4744be2bd73cd8a625a0277d5 | D9: Malang | E9: Paused | F9: Trupti | G9: Mauli | I9: =IFERROR(VLOOKUP($C9,'Show Details'!A:Z,7,0),"") | L9: =SUMIFS(Dump!$D:$D,Dump!$B:$B,$C9,Dump!$A:$A,$V9) -> 0 | M9: =SUMIFS(Dump!R:R,Dump!B:B,C9,Dump!A:A,V9) -> 0 | N9: =K9-L9 -> 0 | P9: =SUMIFS(Dump!E:E,Dump!B:B,C9,Dump!A:A,V9) -> 0 | Q9: =O9-P9 -> 0 | S9: =SUMIFS(Dump!P:P,Dump!B:B,C9,Dump!A:A,V9) -> 0 | T9: =R9-S9 -> 0 | V9: 46146
A10: W1 - May'26 | B10: 81de0bc81be63a15ef7b7f2a301e23b4f3d49745 | D10: Married to a Hard Hearted | F10: Trupti | G10: Monika UGC | I10: =IFERROR(VLOOKUP($C10,'Show Details'!A:Z,7,0),"") | L10: =SUMIFS(Dump!$D:$D,Dump!$B:$B,$C10,Dump!$A:$A,$V10) -> 0 | M10: =SUMIFS(Dump!R:R,Dump!B:B,C10,Dump!A:A,V10) -> 0 | N10: =K10-L10 -> 0 | P10: =SUMIFS(Dump!E:E,Dump!B:B,C10,Dump!A:A,V10) -> 0 | Q10: =O10-P10 -> 0 | S10: =SUMIFS(Dump!P:P,Dump!B:B,C10,Dump!A:A,V10) -> 0 | T10: =R10-S10 -> 0 | V10: 46146
A11: W1 - May'26 | B11: ca6c466ebfcd2658a9f1641045f468c15417a1e7 | D11: My Mysterious Queen | F11: Deepaa | G11: Mona | I11: =IFERROR(VLOOKUP($C11,'Show Details'!A:Z,7,0),"") | L11: =SUMIFS(Dump!$D:$D,Dump!$B:$B,$C11,Dump!$A:$A,$V11) -> 0 | M11: =SUMIFS(Dump!R:R,Dump!B:B,C11,Dump!A:A,V11) -> 0 | N11: =K11-L11 -> 0 | P11: =SUMIFS(Dump!E:E,Dump!B:B,C11,Dump!A:A,V11) -> 0 | Q11: =O11-P11 -> 0 | S11: =SUMIFS(Dump!P:P,Dump!B:B,C11,Dump!A:A,V11) -> 0 | T11: =R11-S11 -> 0 | V11: 46146
A12: W1 - May'26 | C12: aab7b2fa6301b585dcebf9ec60cf4371307ad469 | D12: Tere Ishq Mein | E12: Running | F12: Trupti | G12: Pooja Sharma | I12: =IFERROR(VLOOKUP($C12,'Show Details'!A:Z,7,0),"") | K12: 40 | L12: =SUMIFS(Dump!$D:$D,Dump!$B:$B,$C12,Dump!$A:$A,$V12) -> 30 | M12: =SUMIFS(Dump!R:R,Dump!B:B,C12,Dump!A:A,V12) -> 65086 | N12: =K12-L12 -> 10 | P12: =SUMIFS(Dump!E:E,Dump!B:B,C12,Dump!A:A,V12) -> 34 | Q12: =O12-P12 -> -34 | S12: =SUMIFS(Dump!P:P,Dump!B:B,C12,Dump!A:A,V12) -> 32 | T12: =R12-S12 -> -32 | V12: 46146
A13: W1 - May'26 | B13: 2549f1505a3739b3e90a0b63921ad55271440d40 | D13: Reborn In martial World | F13: Trupti | G13: Prasenjeet | I13: =IFERROR(VLOOKUP($C13,'Show Details'!A:Z,7,0),"") | L13: =SUMIFS(Dump!$D:$D,Dump!$B:$B,$C13,Dump!$A:$A,$V13) -> 0 | M13: =SUMIFS(Dump!R:R,Dump!B:B,C13,Dump!A:A,V13) -> 0 | N13: =K13-L13 -> 0 | P13: =SUMIFS(Dump!E:E,Dump!B:B,C13,Dump!A:A,V13) -> 0 | Q13: =O13-P13 -> 0 | S13: =SUMIFS(Dump!P:P,Dump!B:B,C13,Dump!A:A,V13) -> 0 | T13: =R13-S13 -> 0 | V13: 46146
A14: W1 - May'26 | C14: bb6f447c782519839d8793fda0d35f90bad4421a | D14: Ruthless | E14: Running | F14: Trupti | G14: Prasenjeet | I14: =IFERROR(VLOOKUP($C14,'Show Details'!A:Z,7,0),"") | L14: =SUMIFS(Dump!$D:$D,Dump!$B:$B,$C14,Dump!$A:$A,$V14) -> 0 | M14: =SUMIFS(Dump!R:R,Dump!B:B,C14,Dump!A:A,V14) -> 0 | N14: =K14-L14 -> 0 | P14: =SUMIFS(Dump!E:E,Dump!B:B,C14,Dump!A:A,V14) -> 0 | Q14: =O14-P14 -> 0 | S14: =SUMIFS(Dump!P:P,Dump!B:B,C14,Dump!A:A,V14) -> 8 | T14: =R14-S14 -> -8 | V14: 46146
A15: W1 - May'26 | B15: 37e68193f879e91ec362f75f4b46511110658e2b | C15: 7ea3277f02ef13c60cfa72336d009bf7ee6c17e8 | D15: Saaya the Dark Love | E15: Running | F15: Deepaa | I15: =IFERROR(VLOOKUP($C15,'Show Details'!A:Z,7,0),"") | K15: 10 | L15: =SUMIFS(Dump!$D:$D,Dump!$B:$B,$C15,Dump!$A:$A,$V15) -> 12 | M15: =SUMIFS(Dump!R:R,Dump!B:B,C15,Dump!A:A,V15) -> 24413 | N15: =K15-L15 -> -2 | P15: =SUMIFS(Dump!E:E,Dump!B:B,C15,Dump!A:A,V15) -> 13 | Q15: =O15-P15 -> -13 | S15: =SUMIFS(Dump!P:P,Dump!B:B,C15,Dump!A:A,V15) -> 11 | T15: =R15-S15 -> -11 | V15: 46146
A16: W1 - May'26 | B16: aa81f1feb820ed6f22bd7b22b55890db740929cb | D16: Shunya Samrat | F16: Trupti | G16: Harish (UGC) | I16: =IFERROR(VLOOKUP($C16,'Show Details'!A:Z,7,0),"") | L16: =SUMIFS(Dump!$D:$D,Dump!$B:$B,$C16,Dump!$A:$A,$V16) -> 0 | M16: =SUMIFS(Dump!R:R,Dump!B:B,C16,Dump!A:A,V16) -> 0 | N16: =K16-L16 -> 0 | P16: =SUMIFS(Dump!E:E,Dump!B:B,C16,Dump!A:A,V16) -> 0 | Q16: =O16-P16 -> 0 | S16: =SUMIFS(Dump!P:P,Dump!B:B,C16,Dump!A:A,V16) -> 0 | T16: =R16-S16 -> 0 | V16: 46146
A17: W1 - May'26 | B17: f8fbcb9a13d17d5888164fffc1bbb7cd5c6608b2 | C17: 394d109f7b50d9a46fb591dbaaba2d0aac90a696 | D17: SRGJ / EHK | E17: Running | F17: Asma | G17: Avneet | I17: =IFERROR(VLOOKUP($C17,'Show Details'!A:Z,7,0),"") | L17: =SUMIFS(Dump!$D:$D,Dump!$B:$B,$C17,Dump!$A:$A,$V17) -> 1 | M17: =SUMIFS(Dump!R:R,Dump!B:B,C17,Dump!A:A,V17) -> 2732 | N17: =K17-L17 -> -1 | P17: =SUMIFS(Dump!E:E,Dump!B:B,C17,Dump!A:A,V17) -> 1 | Q17: =O17-P17 -> -1 | S17: =SUMIFS(Dump!P:P,Dump!B:B,C17,Dump!A:A,V17) -> 3 | T17: =R17-S17 -> -3 | V17: 46146
A18: W1 - May'26 | B18: a3ba65aa427077188e1ad7dbcbcafae266683ca9 | C18: 5066c0736f9e9444f2b4da840d6860b1f7f47d11 | D18: The Worrior - Ajith | E18: Running | F18: Deepaa | G18: Dayaram (UGC) + Naznin | I18: =IFERROR(VLOOKUP($C18,'Show Details'!A:Z,7,0),"") | K18: 18 | L18: =SUMIFS(Dump!$D:$D,Dump!$B:$B,$C18,Dump!$A:$A,$V18) -> 354 | M18: =SUMIFS(Dump!R:R,Dump!B:B,C18,Dump!A:A,V18) -> 882175 | N18: =K18-L18 -> -336 | P18: =SUMIFS(Dump!E:E,Dump!B:B,C18,Dump!A:A,V18) -> 25 | Q18: =O18-P18 -> -25 | S18: =SUMIFS(Dump!P:P,Dump!B:B,C18,Dump!A:A,V18) -> 20 | T18: =R18-S18 -> -20 | V18: 46146
A19: W1 - May'26 | C19: 017fddbaa7617afdd8289be5c433df09dcde1da2 | D19: His Secret Fortune | E19: Running | F19: Trupti | G19: Pooja Sharma | I19: =IFERROR(VLOOKUP($C19,'Show Details'!A:Z,7,0),"") | L19: =SUMIFS(Dump!$D:$D,Dump!$B:$B,$C19,Dump!$A:$A,$V19) -> 23 | M19: =SUMIFS(Dump!R:R,Dump!B:B,C19,Dump!A:A,V19) -> 56248 | N19: =K19-L19 -> -23 | P19: =SUMIFS(Dump!E:E,Dump!B:B,C19,Dump!A:A,V19) -> 14 | Q19: =O19-P19 -> -14 | S19: =SUMIFS(Dump!P:P,Dump!B:B,C19,Dump!A:A,V19) -> 24 | T19: =R19-S19 -> -24 | V19: 46146
A20: W1 - May'26 | C20: b236b697a3dda78049a484b58d63a75f4503ad66 | D20: Rudra - Rise of the Supreme Yoddha | E20: Paused | F20: Deepaa | G20: Atrij | I20: =IFERROR(VLOOKUP($C20,'Show Details'!A:Z,7,0),"") | L20: =SUMIFS(Dump!$D:$D,Dump!$B:$B,$C20,Dump!$A:$A,$V20) -> 0 | M20: =SUMIFS(Dump!R:R,Dump!B:B,C20,Dump!A:A,V20) -> 0 | N20: =K20-L20 -> 0 | P20: =SUMIFS(Dump!E:E,Dump!B:B,C20,Dump!A:A,V20) -> 0 | Q20: =O20-P20 -> 0 | S20: =SUMIFS(Dump!P:P,Dump!B:B,C20,Dump!A:A,V20) -> 0 | T20: =R20-S20 -> 0 | V20: 46146
A21: W1 - May'26 | C21: b4277fe045604b0c31d4c58c59733d8d995662ff | D21: Divine Power | E21: Paused | F21: Shivam | I21: =IFERROR(VLOOKUP($C21,'Show Details'!A:Z,7,0),"") | L21: =SUMIFS(Dump!$D:$D,Dump!$B:$B,$C21,Dump!$A:$A,$V21) -> 0 | M21: =SUMIFS(Dump!R:R,Dump!B:B,C21,Dump!A:A,V21) -> 0 | N21: =K21-L21 -> 0 | P21: =SUMIFS(Dump!E:E,Dump!B:B,C21,Dump!A:A,V21) -> 0 | Q21: =O21-P21 -> 0 | S21: =SUMIFS(Dump!P:P,Dump!B:B,C21,Dump!A:A,V21) -> 0 | T21: =R21-S21 -> 0 | V21: 46146
A22: W1 - May'26 | C22: ef9669389baf6711142a1ec22c3505fc714d91c0 | D22: Abhimanyu Legend Yoddha | I22: =IFERROR(VLOOKUP($C22,'Show Details'!A:Z,7,0),"") | L22: =SUMIFS(Dump!$D:$D,Dump!$B:$B,$C22,Dump!$A:$A,$V22) -> 0 | M22: =SUMIFS(Dump!R:R,Dump!B:B,C22,Dump!A:A,V22) -> 0 | N22: =K22-L22 -> 0 | P22: =SUMIFS(Dump!E:E,Dump!B:B,C22,Dump!A:A,V22) -> 0 | Q22: =O22-P22 -> 0 | S22: =SUMIFS(Dump!P:P,Dump!B:B,C22,Dump!A:A,V22) -> 0 | T22: =R22-S22 -> 0 | V22: 46146
A23: W1 - May'26 | C23: c6ddafe0c1c28e76700ec68e65063945a05ee155 | D23: Reborn to Rule | E23: Running | I23: =IFERROR(VLOOKUP($C23,'Show Details'!A:Z,7,0),"") | K23: 20 | L23: =SUMIFS(Dump!$D:$D,Dump!$B:$B,$C23,Dump!$A:$A,$V23) -> 19 | M23: =SUMIFS(Dump!R:R,Dump!B:B,C23,Dump!A:A,V23) -> 41346 | N23: =K23-L23 -> 1 | P23: =SUMIFS(Dump!E:E,Dump!B:B,C23,Dump!A:A,V23) -> 0 | Q23: =O23-P23 -> 0 | S23: =SUMIFS(Dump!P:P,Dump!B:B,C23,Dump!A:A,V23) -> 0 | T23: =R23-S23 -> 0 | V23: 46146
A24: W1 - May'26 | C24: b19f613216d474cd2927d5f4832a949dca2dc33e | D24: The Immortal | E24: Paused | F24: Trupti | G24: Mauli | I24: =IFERROR(VLOOKUP($C24,'Show Details'!A:Z,7,0),"") | L24: =SUMIFS(Dump!$D:$D,Dump!$B:$B,$C24,Dump!$A:$A,$V24) -> 0 | M24: =SUMIFS(Dump!R:R,Dump!B:B,C24,Dump!A:A,V24) -> 0 | N24: =K24-L24 -> 0 | P24: =SUMIFS(Dump!E:E,Dump!B:B,C24,Dump!A:A,V24) -> 0 | Q24: =O24-P24 -> 0 | S24: =SUMIFS(Dump!P:P,Dump!B:B,C24,Dump!A:A,V24) -> 0 | T24: =R24-S24 -> 0 | V24: 46146
A25: W1 - May'26 | C25: 6b246320a4c5853ce55127d5e00ee8805a97659a | D25: Mystic Fate System | E25: Paused | F25: Deepaa | G25: March W1 | I25: =IFERROR(VLOOKUP($C25,'Show Details'!A:Z,7,0),"") | L25: =SUMIFS(Dump!$D:$D,Dump!$B:$B,$C25,Dump!$A:$A,$V25) -> 0 | M25: =SUMIFS(Dump!R:R,Dump!B:B,C25,Dump!A:A,V25) -> 0 | N25: =K25-L25 -> 0 | P25: =SUMIFS(Dump!E:E,Dump!B:B,C25,Dump!A:A,V25) -> 0 | Q25: =O25-P25 -> 0 | S25: =SUMIFS(Dump!P:P,Dump!B:B,C25,Dump!A:A,V25) -> 1 | T25: =R25-S25 -> -1 | V25: 46146
A26: W1 - May'26 | C26: 120f01928bb6593698eaa96f46a52b5ddab649bd | D26: Beggar Husband - 2 | E26: Running | I26: =IFERROR(VLOOKUP($C26,'Show Details'!A:Z,7,0),"") | K26: 12 | L26: =SUMIFS(Dump!$D:$D,Dump!$B:$B,$C26,Dump!$A:$A,$V26) -> 15 | M26: =SUMIFS(Dump!R:R,Dump!B:B,C26,Dump!A:A,V26) -> 33622 | N26: =K26-L26 -> -3 | P26: =SUMIFS(Dump!E:E,Dump!B:B,C26,Dump!A:A,V26) -> 19 | Q26: =O26-P26 -> -19 | S26: =SUMIFS(Dump!P:P,Dump!B:B,C26,Dump!A:A,V26) -> 21 | T26: =R26-S26 -> -21 | V26: 46146
A27: W1 - May'26 | C27: 2f705add1a4571e3dcc4eb1426edfaa372c9cee8 | D27: Beggar Husband - Pnakaj | E27: Paused | F27: Shivam | G27: March W1 | I27: =IFERROR(VLOOKUP($C27,'Show Details'!A:Z,7,0),"") | L27: =SUMIFS(Dump!$D:$D,Dump!$B:$B,$C27,Dump!$A:$A,$V27) -> 0 | M27: =SUMIFS(Dump!R:R,Dump!B:B,C27,Dump!A:A,V27) -> 0 | N27: =K27-L27 -> 0 | P27: =SUMIFS(Dump!E:E,Dump!B:B,C27,Dump!A:A,V27) -> 0 | Q27: =O27-P27 -> 0 | S27: =SUMIFS(Dump!P:P,Dump!B:B,C27,Dump!A:A,V27) -> 0 | T27: =R27-S27 -> 0 | V27: 46146
A28: W1 - May'26 | C28: 5a7d21f6ad9df12be70cd9439dd850c36627991d | D28: Ek stranger se Pyaar | E28: Running | F28: Trupti | G28: Atrij | I28: =IFERROR(VLOOKUP($C28,'Show Details'!A:Z,7,0),"") | K28: 30 | L28: =SUMIFS(Dump!$D:$D,Dump!$B:$B,$C28,Dump!$A:$A,$V28) -> 29 | M28: =SUMIFS(Dump!R:R,Dump!B:B,C28,Dump!A:A,V28) -> 69012 | N28: =K28-L28 -> 1 | P28: =SUMIFS(Dump!E:E,Dump!B:B,C28,Dump!A:A,V28) -> 11 | Q28: =O28-P28 -> -11 | S28: =SUMIFS(Dump!P:P,Dump!B:B,C28,Dump!A:A,V28) -> 19 | T28: =R28-S28 -> -19 | V28: 46146
A29: W1 - May'26 | C29: 6867922e795be5da6320ef1d28567452800209ba | D29: The Dimension God | E29: Running | F29: Trupti | I29: =IFERROR(VLOOKUP($C29,'Show Details'!A:Z,7,0),"") | K29: 30 | L29: =SUMIFS(Dump!$D:$D,Dump!$B:$B,$C29,Dump!$A:$A,$V29) -> 30 | M29: =SUMIFS(Dump!R:R,Dump!B:B,C29,Dump!A:A,V29) -> 72191 | N29: =K29-L29 -> 0 | P29: =SUMIFS(Dump!E:E,Dump!B:B,C29,Dump!A:A,V29) -> 5 | Q29: =O29-P29 -> -5 | S29: =SUMIFS(Dump!P:P,Dump!B:B,C29,Dump!A:A,V29) -> 5 | T29: =R29-S29 -> -5 | V29: 46146
A30: W1 - May'26 | C30: 54847eda0794e861da74c1034ace021b4643357b | D30: Billionaire King's love | E30: Paused | F30: Trupti | I30: =IFERROR(VLOOKUP($C30,'Show Details'!A:Z,7,0),"") | L30: =SUMIFS(Dump!$D:$D,Dump!$B:$B,$C30,Dump!$A:$A,$V30) -> 0 | M30: =SUMIFS(Dump!R:R,Dump!B:B,C30,Dump!A:A,V30) -> 0 | N30: =K30-L30 -> 0 | P30: =SUMIFS(Dump!E:E,Dump!B:B,C30,Dump!A:A,V30) -> 0 | Q30: =O30-P30 -> 0 | S30: =SUMIFS(Dump!P:P,Dump!B:B,C30,Dump!A:A,V30) -> 0 | T30: =R30-S30 -> 0 | V30: 46146
A31: W1 - May'26 | C31: 1b4ecb8a0d96b42675a2bbd2a9bd28ef4d28a0dd | D31: Doctor Mafia King | I31: =IFERROR(VLOOKUP($C31,'Show Details'!A:Z,7,0),"") | L31: =SUMIFS(Dump!$D:$D,Dump!$B:$B,$C31,Dump!$A:$A,$V31) -> 0 | M31: =SUMIFS(Dump!R:R,Dump!B:B,C31,Dump!A:A,V31) -> 0 | N31: =K31-L31 -> 0 | P31: =SUMIFS(Dump!E:E,Dump!B:B,C31,Dump!A:A,V31) -> 0 | Q31: =O31-P31 -> 0 | S31: =SUMIFS(Dump!P:P,Dump!B:B,C31,Dump!A:A,V31) -> 0 | T31: =R31-S31 -> 0 | V31: 46146
A32: W1 - May'26 | C32: 9afaea00813dcb4fc57a46df70a2e3e1066af919 | D32: My millionaire system | E32: Running | I32: =IFERROR(VLOOKUP($C32,'Show Details'!A:Z,7,0),"") | K32: 10 | L32: =SUMIFS(Dump!$D:$D,Dump!$B:$B,$C32,Dump!$A:$A,$V32) -> 20 | M32: =SUMIFS(Dump!R:R,Dump!B:B,C32,Dump!A:A,V32) -> 43065 | N32: =K32-L32 -> -10 | P32: =SUMIFS(Dump!E:E,Dump!B:B,C32,Dump!A:A,V32) -> 12 | Q32: =O32-P32 -> -12 | S32: =SUMIFS(Dump!P:P,Dump!B:B,C32,Dump!A:A,V32) -> 14 | T32: =R32-S32 -> -14 | V32: 46146
A33: W1 - May'26 | C33: 661dba879cabc615ad2774813367b442a8ba7a6c | D33: My Devil Wife | I33: =IFERROR(VLOOKUP($C33,'Show Details'!A:Z,7,0),"") | L33: =SUMIFS(Dump!$D:$D,Dump!$B:$B,$C33,Dump!$A:$A,$V33) -> 13 | M33: =SUMIFS(Dump!R:R,Dump!B:B,C33,Dump!A:A,V33) -> 30909 | N33: =K33-L33 -> -13 | P33: =SUMIFS(Dump!E:E,Dump!B:B,C33,Dump!A:A,V33) -> 0 | Q33: =O33-P33 -> 0 | S33: =SUMIFS(Dump!P:P,Dump!B:B,C33,Dump!A:A,V33) -> 0 | T33: =R33-S33 -> 0 | V33: 46146
A34: W1 - May'26 | C34: =IFERROR(VLOOKUP(D34,Sheet3!L:M,2,0),"") | D34: The Legend Gods | I34: =IFERROR(VLOOKUP($C34,'Show Details'!A:Z,7,0),"") | L34: =SUMIFS(Dump!$D:$D,Dump!$B:$B,$C34,Dump!$A:$A,$V34) -> 0 | M34: =SUMIFS(Dump!R:R,Dump!B:B,C34,Dump!A:A,V34) -> 0 | N34: =K34-L34 -> 0 | P34: =SUMIFS(Dump!E:E,Dump!B:B,C34,Dump!A:A,V34) -> 0 | Q34: =O34-P34 -> 0 | S34: =SUMIFS(Dump!P:P,Dump!B:B,C34,Dump!A:A,V34) -> 0 | T34: =R34-S34 -> 0 | V34: 46146
A35: W1 - May'26 | C35: =IFERROR(VLOOKUP(D35,Sheet3!L:M,2,0),"") | D35: Hidden King | I35: =IFERROR(VLOOKUP($C35,'Show Details'!A:Z,7,0),"") | L35: =SUMIFS(Dump!$D:$D,Dump!$B:$B,$C35,Dump!$A:$A,$V35) -> 0 | M35: =SUMIFS(Dump!R:R,Dump!B:B,C35,Dump!A:A,V35) -> 0 | N35: =K35-L35 -> 0 | P35: =SUMIFS(Dump!E:E,Dump!B:B,C35,Dump!A:A,V35) -> 0 | Q35: =O35-P35 -> 0 | S35: =SUMIFS(Dump!P:P,Dump!B:B,C35,Dump!A:A,V35) -> 0 | T35: =R35-S35 -> 0 | V35: 46146
A36: W1 - May'26 | C36: =IFERROR(VLOOKUP(D36,Sheet3!L:M,2,0),"") | D36: Devil's Revenge | डेविल्स रिवेंज | Author - Pawan Kumar | F36: =IFERROR(VLOOKUP($D36,Sheet3!$N:$Q,3,0),"") | G36: =IFERROR(VLOOKUP($D36,Sheet3!$N:$Q,4,0),"") | I36: =IFERROR(VLOOKUP($C36,'Show Details'!A:Z,7,0),"") | L36: =SUMIFS(Dump!$D:$D,Dump!$B:$B,$C36,Dump!$A:$A,$V36) -> 0 | M36: =SUMIFS(Dump!R:R,Dump!B:B,C36,Dump!A:A,V36) -> 0 | N36: =K36-L36 -> 0 | P36: =SUMIFS(Dump!E:E,Dump!B:B,C36,Dump!A:A,V36) -> 0 | Q36: =O36-P36 -> 0 | S36: =SUMIFS(Dump!P:P,Dump!B:B,C36,Dump!A:A,V36) -> 0 | T36: =R36-S36 -> 0 | V36: 46146
A37: W1 - May'26 | C37: =IFERROR(VLOOKUP(D37,Sheet3!L:M,2,0),"") | D37: Supreme Ansh: Protector or Destroyer | सुप्रीम अंश प्रोटेक्टर या डिस्ट्रॉयर | Author - Shubham | F37: =IFERROR(VLOOKUP($D37,Sheet3!$N:$Q,3,0),"") | G37: =IFERROR(VLOOKUP($D37,Sheet3!$N:$Q,4,0),"") | I37: =IFERROR(VLOOKUP($C37,'Show Details'!A:Z,7,0),"") | L37: =SUMIFS(Dump!$D:$D,Dump!$B:$B,$C37,Dump!$A:$A,$V37) -> 0 | M37: =SUMIFS(Dump!R:R,Dump!B:B,C37,Dump!A:A,V37) -> 0 | N37: =K37-L37 -> 0 | P37: =SUMIFS(Dump!E:E,Dump!B:B,C37,Dump!A:A,V37) -> 0 | Q37: =O37-P37 -> 0 | S37: =SUMIFS(Dump!P:P,Dump!B:B,C37,Dump!A:A,V37) -> 0 | T37: =R37-S37 -> 0 | V37: 46146
A39: W2 - May'26 | B39: dbbc7f35e9eb33b7562f0fd82896e827101bf13c | C39: b9727274f880f47671ad54caad4904a491fad9c7 | D39: Brahmand Ka Rakshak | E39: Running | F39: Trupti | G39: Vijay | I39: =IFERROR(VLOOKUP($C39,'Show Details'!A:Z,7,0),"") | K39: =IFERROR(VLOOKUP(C39,Sheet10!C:J,8,0),"") | L39: =SUMIFS(Dump!$D:$D,Dump!$B:$B,$C39,Dump!$A:$A,$V39) -> 11 | M39: =SUMIFS(Dump!R:R,Dump!B:B,C39,Dump!A:A,V39) -> 26730 | N39: =K39-L39 -> -11 | P39: =SUMIFS(Dump!E:E,Dump!B:B,C39,Dump!A:A,V39) -> 32 | Q39: =O39-P39 -> -32 | S39: =SUMIFS(Dump!P:P,Dump!B:B,C39,Dump!A:A,V39) -> 3 | T39: =R39-S39 -> -3 | V39: 46153
A40: W2 - May'26 | B40: f43f4253dc3c596ff8f2e3cc9f3b677981a70310 | C40: 5baf4c80faf4b2d4eb9401a1d0081872e0158e89 | D40: Brahmyodha the Destroyer | E40: Running | F40: Deepaa | G40: Shivani | I40: =IFERROR(VLOOKUP($C40,'Show Details'!A:Z,7,0),"") | K40: =IFERROR(VLOOKUP(C40,Sheet10!C:J,8,0),"") | L40: =SUMIFS(Dump!$D:$D,Dump!$B:$B,$C40,Dump!$A:$A,$V40) -> 11 | M40: =SUMIFS(Dump!R:R,Dump!B:B,C40,Dump!A:A,V40) -> 24161 | N40: =K40-L40 -> -11 | P40: =SUMIFS(Dump!E:E,Dump!B:B,C40,Dump!A:A,V40) -> 8 | Q40: =O40-P40 -> -8 | S40: =SUMIFS(Dump!P:P,Dump!B:B,C40,Dump!A:A,V40) -> 10 | T40: =R40-S40 -> -10 | V40: 46153
A41: W2 - May'26 | B41: 859785ba4869b28dddcfcb0e75295d1e1ad9b5a9 | C41: 96f1f89e4494e06fb7f9e3c4645563fa62ef9320 | D41: King of Dragon | E41: Running | F41: Deepaa | G41: Amit Rajak | I41: =IFERROR(VLOOKUP($C41,'Show Details'!A:Z,7,0),"") | K41: =IFERROR(VLOOKUP(C41,Sheet10!C:J,8,0),"") | L41: =SUMIFS(Dump!$D:$D,Dump!$B:$B,$C41,Dump!$A:$A,$V41) -> 10 | M41: =SUMIFS(Dump!R:R,Dump!B:B,C41,Dump!A:A,V41) -> 24505 | N41: =K41-L41 -> -10 | P41: =SUMIFS(Dump!E:E,Dump!B:B,C41,Dump!A:A,V41) -> 8 | Q41: =O41-P41 -> -8 | S41: =SUMIFS(Dump!P:P,Dump!B:B,C41,Dump!A:A,V41) -> 4 | T41: =R41-S41 -> -4 | V41: 46153
A42: W2 - May'26 | B42: 641b6f77fd211e92df35a3bcbab67e6879e19a66 | C42: 773d29931b435627d0ca406e1ea1425e9a1dbcb6 | D42: Mahagatha | F42: Shivam | G42: NItesh | I42: =IFERROR(VLOOKUP($C42,'Show Details'!A:Z,7,0),"") | K42: =IFERROR(VLOOKUP(C42,Sheet10!C:J,8,0),"") | L42: =SUMIFS(Dump!$D:$D,Dump!$B:$B,$C42,Dump!$A:$A,$V42) -> 18 | M42: =SUMIFS(Dump!R:R,Dump!B:B,C42,Dump!A:A,V42) -> 52058 | N42: =K42-L42 -> -18 | P42: =SUMIFS(Dump!E:E,Dump!B:B,C42,Dump!A:A,V42) -> 16 | Q42: =O42-P42 -> -16 | S42: =SUMIFS(Dump!P:P,Dump!B:B,C42,Dump!A:A,V42) -> 9 | T42: =R42-S42 -> -9 | V42: 46153
A43: W2 - May'26 | B43: e493cee863483a057af12de782cd20043a19ed05 | C43: 4c7fcc2bad9d3ae4744be2bd73cd8a625a0277d5 | D43: Malang | E43: Paused | F43: Trupti | G43: Mauli | I43: =IFERROR(VLOOKUP($C43,'Show Details'!A:Z,7,0),"") | K43: =IFERROR(VLOOKUP(C43,Sheet10!C:J,8,0),"") | L43: =SUMIFS(Dump!$D:$D,Dump!$B:$B,$C43,Dump!$A:$A,$V43) -> 0 | M43: =SUMIFS(Dump!R:R,Dump!B:B,C43,Dump!A:A,V43) -> 0 | N43: =K43-L43 -> 0 | P43: =SUMIFS(Dump!E:E,Dump!B:B,C43,Dump!A:A,V43) -> 0 | Q43: =O43-P43 -> 0 | S43: =SUMIFS(Dump!P:P,Dump!B:B,C43,Dump!A:A,V43) -> 0 | T43: =R43-S43 -> 0 | V43: 46153
...

Sheet Dump
A1: =IFERROR(__xludf.DUMMYFUNCTION("IMPORTRANGE(""1O5ZrS1LfZUtRkCMJG2qtT5s25b1YyUxbOioc5QK37Lk"",""Master!G:AL"")"),"Period") -> Period | B1: =IFERROR(__xludf.DUMMYFUNCTION("""COMPUTED_VALUE"""),"Show ID") -> Show ID | C1: =IFERROR(__xludf.DUMMYFUNCTION("""COMPUTED_VALUE"""),"Show Title") -> Show Title | D1: =IFERROR(__xludf.DUMMYFUNCTION("""COMPUTED_VALUE"""),"Under Review (scripts)") -> Under Review (scripts) | E1: =IFERROR(__xludf.DUMMYFUNCTION("""COMPUTED_VALUE"""),"Approved (scripts)") -> Approved (scripts) | F1: =IFERROR(__xludf.DUMMYFUNCTION("""COMPUTED_VALUE"""),"Issues in Raw (eps)") -> Issues in Raw (eps) | G1: =IFERROR(__xludf.DUMMYFUNCTION("""COMPUTED_VALUE"""),"Issues resolved in Raw (eps)") -> Issues resolved in Raw (eps) | H1: =IFERROR(__xludf.DUMMYFUNCTION("""COMPUTED_VALUE"""),"Production (eps)") -> Production (eps) | I1: =IFERROR(__xludf.DUMMYFUNCTION("""COMPUTED_VALUE"""),"Ready for Master (eps)") -> Ready for Master (eps) | J1: =IFERROR(__xludf.DUMMYFUNCTION("""COMPUTED_VALUE"""),"Master under review (eps)") -> Master under review (eps) | K1: =IFERROR(__xludf.DUMMYFUNCTION("""COMPUTED_VALUE"""),"Issues in Master (eps)") -> Issues in Master (eps) | L1: =IFERROR(__xludf.DUMMYFUNCTION("""COMPUTED_VALUE"""),"Issues resolved in Master (eps)") -> Issues resolved in Master (eps) | M1: =IFERROR(__xludf.DUMMYFUNCTION("""COMPUTED_VALUE"""),"Final Master (eps)") -> Final Master (eps) | N1: =IFERROR(__xludf.DUMMYFUNCTION("""COMPUTED_VALUE"""),"Master Approved (eps)") -> Master Approved (eps) | O1: =IFERROR(__xludf.DUMMYFUNCTION("""COMPUTED_VALUE"""),"Scheduled (eps)") -> Scheduled (eps) | P1: =IFERROR(__xludf.DUMMYFUNCTION("""COMPUTED_VALUE"""),"Released (eps)") -> Released (eps) | Q1: =IFERROR(__xludf.DUMMYFUNCTION("""COMPUTED_VALUE"""),"__") -> __ | R1: =IFERROR(__xludf.DUMMYFUNCTION("""COMPUTED_VALUE"""),"Under Review (word count)") -> Under Review (word count) | S1: =IFERROR(__xludf.DUMMYFUNCTION("""COMPUTED_VALUE"""),"Approved (word count)") -> Approved (word count) | T1: =IFERROR(__xludf.DUMMYFUNCTION("""COMPUTED_VALUE"""),"Raw under review (hr)") -> Raw under review (hr) | U1: =IFERROR(__xludf.DUMMYFUNCTION("""COMPUTED_VALUE"""),"Issues in Raw (hr)") -> Issues in Raw (hr) | V1: =IFERROR(__xludf.DUMMYFUNCTION("""COMPUTED_VALUE"""),"Issues resolved in Raw (hr)") -> Issues resolved in Raw (hr) | W1: =IFERROR(__xludf.DUMMYFUNCTION("""COMPUTED_VALUE"""),"Production (hr)") -> Production (hr) | X1: =IFERROR(__xludf.DUMMYFUNCTION("""COMPUTED_VALUE"""),"Ready for Master (hr)") -> Ready for Master (hr) | Y1: =IFERROR(__xludf.DUMMYFUNCTION("""COMPUTED_VALUE"""),"Master under review (hr)") -> Master under review (hr) | Z1: =IFERROR(__xludf.DUMMYFUNCTION("""COMPUTED_VALUE"""),"Issues in Master (hr)") -> Issues in Master (hr) | AA1: =IFERROR(__xludf.DUMMYFUNCTION("""COMPUTED_VALUE"""),"Issues resolved in Master (hr)") -> Issues resolved in Master (hr) | AB1: =IFERROR(__xludf.DUMMYFUNCTION("""COMPUTED_VALUE"""),"Final Master (hr)") -> Final Master (hr) | AC1: =IFERROR(__xludf.DUMMYFUNCTION("""COMPUTED_VALUE"""),"Master Approved (hr)") -> Master Approved (hr) | AD1: =IFERROR(__xludf.DUMMYFUNCTION("""COMPUTED_VALUE"""),"Scheduled (hr)") -> Scheduled (hr) | AE1: =IFERROR(__xludf.DUMMYFUNCTION("""COMPUTED_VALUE"""),"Released (hr)") -> Released (hr) | AF1: =IFERROR(__xludf.DUMMYFUNCTION("""COMPUTED_VALUE"""),"chapters_raw_qc") -> chapters_raw_qc
A2: =IFERROR(__xludf.DUMMYFUNCTION("""COMPUTED_VALUE"""),46153.0) -> 46153 | B2: =IFERROR(__xludf.DUMMYFUNCTION("""COMPUTED_VALUE"""),"017fddbaa7617afdd8289be5c433df09dcde1da2") -> 017fddbaa7617afdd8289be5c433df09dcde1da2 | C2: =IFERROR(__xludf.DUMMYFUNCTION("""COMPUTED_VALUE"""),"His Secret Fortune - Production Show_id") -> His Secret Fortune - Production Show_id | D2: =IFERROR(__xludf.DUMMYFUNCTION("""COMPUTED_VALUE"""),18.0) -> 18 | E2: =IFERROR(__xludf.DUMMYFUNCTION("""COMPUTED_VALUE"""),29.0) -> 29 | F2: =IFERROR(__xludf.DUMMYFUNCTION("""COMPUTED_VALUE"""),11.0) -> 11 | G2: =IFERROR(__xludf.DUMMYFUNCTION("""COMPUTED_VALUE"""),6.0) -> 6 | H2: =IFERROR(__xludf.DUMMYFUNCTION("""COMPUTED_VALUE"""),8.0) -> 8 | I2: =IFERROR(__xludf.DUMMYFUNCTION("""COMPUTED_VALUE"""),3.0) -> 3 | J2: =IFERROR(__xludf.DUMMYFUNCTION("""COMPUTED_VALUE"""),6.0) -> 6 | K2: =IFERROR(__xludf.DUMMYFUNCTION("""COMPUTED_VALUE"""),3.0) -> 3 | L2: =IFERROR(__xludf.DUMMYFUNCTION("""COMPUTED_VALUE"""),1.0) -> 1 | M2: =IFERROR(__xludf.DUMMYFUNCTION("""COMPUTED_VALUE"""),6.0) -> 6 | N2: =IFERROR(__xludf.DUMMYFUNCTION("""COMPUTED_VALUE"""),13.0) -> 13 | O2: =IFERROR(__xludf.DUMMYFUNCTION("""COMPUTED_VALUE"""),3.0) -> 3 | P2: =IFERROR(__xludf.DUMMYFUNCTION("""COMPUTED_VALUE"""),13.0) -> 13 | Q2: =IFERROR(__xludf.DUMMYFUNCTION("""COMPUTED_VALUE"""),0.0) -> 0 | R2: =IFERROR(__xludf.DUMMYFUNCTION("""COMPUTED_VALUE"""),42267.0) -> 42267 | S2: =IFERROR(__xludf.DUMMYFUNCTION("""COMPUTED_VALUE"""),68750.0) -> 68750 | T2: =IFERROR(__xludf.DUMMYFUNCTION("""COMPUTED_VALUE"""),2.56333333333333) -> 2.5633333 | U2: =IFERROR(__xludf.DUMMYFUNCTION("""COMPUTED_VALUE"""),2.34888888888888) -> 2.3488889 | V2: =IFERROR(__xludf.DUMMYFUNCTION("""COMPUTED_VALUE"""),1.29361111111111) -> 1.2936111 | W2: =IFERROR(__xludf.DUMMYFUNCTION("""COMPUTED_VALUE"""),1.72888888888888) -> 1.7288889 | X2: =IFERROR(__xludf.DUMMYFUNCTION("""COMPUTED_VALUE"""),0.661666666666666) -> 0.66166667 | Y2: =IFERROR(__xludf.DUMMYFUNCTION("""COMPUTED_VALUE"""),1.29611111111111) -> 1.2961111 | Z2: =IFERROR(__xludf.DUMMYFUNCTION("""COMPUTED_VALUE"""),0.656388888888888) -> 0.65638889 | AA2: =IFERROR(__xludf.DUMMYFUNCTION("""COMPUTED_VALUE"""),0.221388888888888) -> 0.22138889 | AB2: =IFERROR(__xludf.DUMMYFUNCTION("""COMPUTED_VALUE"""),1.32861111111111) -> 1.3286111 | AC2: =IFERROR(__xludf.DUMMYFUNCTION("""COMPUTED_VALUE"""),2.81833333333333) -> 2.8183333 | AD2: =IFERROR(__xludf.DUMMYFUNCTION("""COMPUTED_VALUE"""),0.597499999999999) -> 0.5975 | AE2: =IFERROR(__xludf.DUMMYFUNCTION("""COMPUTED_VALUE"""),2.81833333333333) -> 2.8183333 | AF2: =IFERROR(__xludf.DUMMYFUNCTION("""COMPUTED_VALUE"""),12.0) -> 12
A3: =IFERROR(__xludf.DUMMYFUNCTION("""COMPUTED_VALUE"""),46153.0) -> 46153 | B3: =IFERROR(__xludf.DUMMYFUNCTION("""COMPUTED_VALUE"""),"120f01928bb6593698eaa96f46a52b5ddab649bd") -> 120f01928bb6593698eaa96f46a52b5ddab649bd | C3: =IFERROR(__xludf.DUMMYFUNCTION("""COMPUTED_VALUE"""),"Beggar Husband - 2") -> Beggar Husband - 2 | D3: =IFERROR(__xludf.DUMMYFUNCTION("""COMPUTED_VALUE"""),11.0) -> 11 | E3: =IFERROR(__xludf.DUMMYFUNCTION("""COMPUTED_VALUE"""),9.0) -> 9 | F3: =IFERROR(__xludf.DUMMYFUNCTION("""COMPUTED_VALUE"""),0.0) -> 0 | G3: =IFERROR(__xludf.DUMMYFUNCTION("""COMPUTED_VALUE"""),0.0) -> 0 | H3: =IFERROR(__xludf.DUMMYFUNCTION("""COMPUTED_VALUE"""),0.0) -> 0 | I3: =IFERROR(__xludf.DUMMYFUNCTION("""COMPUTED_VALUE"""),0.0) -> 0 | J3: =IFERROR(__xludf.DUMMYFUNCTION("""COMPUTED_VALUE"""),0.0) -> 0 | K3: =IFERROR(__xludf.DUMMYFUNCTION("""COMPUTED_VALUE"""),0.0) -> 0 | L3: =IFERROR(__xludf.DUMMYFUNCTION("""COMPUTED_VALUE"""),0.0) -> 0 | M3: =IFERROR(__xludf.DUMMYFUNCTION("""COMPUTED_VALUE"""),7.0) -> 7 | N3: =IFERROR(__xludf.DUMMYFUNCTION("""COMPUTED_VALUE"""),7.0) -> 7 | O3: =IFERROR(__xludf.DUMMYFUNCTION("""COMPUTED_VALUE"""),3.0) -> 3 | P3: =IFERROR(__xludf.DUMMYFUNCTION("""COMPUTED_VALUE"""),7.0) -> 7 | Q3: =IFERROR(__xludf.DUMMYFUNCTION("""COMPUTED_VALUE"""),0.0) -> 0 | R3: =IFERROR(__xludf.DUMMYFUNCTION("""COMPUTED_VALUE"""),24076.0) -> 24076 | S3: =IFERROR(__xludf.DUMMYFUNCTION("""COMPUTED_VALUE"""),19692.0) -> 19692 | T3: =IFERROR(__xludf.DUMMYFUNCTION("""COMPUTED_VALUE"""),0.505833333333333) -> 0.50583333 | U3: =IFERROR(__xludf.DUMMYFUNCTION("""COMPUTED_VALUE"""),0.0) -> 0 | V3: =IFERROR(__xludf.DUMMYFUNCTION("""COMPUTED_VALUE"""),0.0) -> 0 | W3: =IFERROR(__xludf.DUMMYFUNCTION("""COMPUTED_VALUE"""),0.0) -> 0 | X3: =IFERROR(__xludf.DUMMYFUNCTION("""COMPUTED_VALUE"""),0.0) -> 0 | Y3: =IFERROR(__xludf.DUMMYFUNCTION("""COMPUTED_VALUE"""),0.0) -> 0 | Z3: =IFERROR(__xludf.DUMMYFUNCTION("""COMPUTED_VALUE"""),0.0) -> 0 | AA3: =IFERROR(__xludf.DUMMYFUNCTION("""COMPUTED_VALUE"""),0.0) -> 0 | AB3: =IFERROR(__xludf.DUMMYFUNCTION("""COMPUTED_VALUE"""),1.67333333333333) -> 1.6733333 | AC3: =IFERROR(__xludf.DUMMYFUNCTION("""COMPUTED_VALUE"""),1.67277777777777) -> 1.6727778 | AD3: =IFERROR(__xludf.DUMMYFUNCTION("""COMPUTED_VALUE"""),0.669444444444444) -> 0.66944444 | AE3: =IFERROR(__xludf.DUMMYFUNCTION("""COMPUTED_VALUE"""),1.67277777777777) -> 1.6727778 | AF3: =IFERROR(__xludf.DUMMYFUNCTION("""COMPUTED_VALUE"""),2.0) -> 2
A4: =IFERROR(__xludf.DUMMYFUNCTION("""COMPUTED_VALUE"""),46153.0) -> 46153 | B4: =IFERROR(__xludf.DUMMYFUNCTION("""COMPUTED_VALUE"""),"37e68193f879e91ec362f75f4b46511110658e2b") -> 37e68193f879e91ec362f75f4b46511110658e2b | C4: =IFERROR(__xludf.DUMMYFUNCTION("""COMPUTED_VALUE"""),"Shiva : Ek Pretyodha") -> Shiva : Ek Pretyodha | D4: =IFERROR(__xludf.DUMMYFUNCTION("""COMPUTED_VALUE"""),0.0) -> 0 | E4: =IFERROR(__xludf.DUMMYFUNCTION("""COMPUTED_VALUE"""),0.0) -> 0 | F4: =IFERROR(__xludf.DUMMYFUNCTION("""COMPUTED_VALUE"""),0.0) -> 0 | G4: =IFERROR(__xludf.DUMMYFUNCTION("""COMPUTED_VALUE"""),0.0) -> 0 | H4: =IFERROR(__xludf.DUMMYFUNCTION("""COMPUTED_VALUE"""),0.0) -> 0 | I4: =IFERROR(__xludf.DUMMYFUNCTION("""COMPUTED_VALUE"""),0.0) -> 0 | J4: =IFERROR(__xludf.DUMMYFUNCTION("""COMPUTED_VALUE"""),0.0) -> 0 | K4: =IFERROR(__xludf.DUMMYFUNCTION("""COMPUTED_VALUE"""),0.0) -> 0 | ... N4: =IFERROR(__xludf.DUMMYFUNCTION("""COMPUTED_VALUE"""),0.0) -> 0 | O4: =IFERROR(__xludf.DUMMYFUNCTION("""COMPUTED_VALUE"""),8.0) -> 8 | P4: =IFERROR(__xludf.DUMMYFUNCTION("""COMPUTED_VALUE"""),14.0) -> 14 | Q4: =IFERROR(__xludf.DUMMYFUNCTION("""COMPUTED_VALUE"""),0.0) -> 0 | R4: =IFERROR(__xludf.DUMMYFUNCTION("""COMPUTED_VALUE"""),0.0) -> 0 | S4: =IFERROR(__xludf.DUMMYFUNCTION("""COMPUTED_VALUE"""),0.0) -> 0 | T4: =IFERROR(__xludf.DUMMYFUNCTION("""COMPUTED_VALUE"""),0.0) -> 0 | U4: =IFERROR(__xludf.DUMMYFUNCTION("""COMPUTED_VALUE"""),0.0) -> 0 | V4: =IFERROR(__xludf.DUMMYFUNCTION("""COMPUTED_VALUE"""),0.0) -> 0 | W4: =IFERROR(__xludf.DUMMYFUNCTION("""COMPUTED_VALUE"""),0.0) -> 0 | X4: =IFERROR(__xludf.DUMMYFUNCTION("""COMPUTED_VALUE"""),0.0) -> 0 | ... AC4: =IFERROR(__xludf.DUMMYFUNCTION("""COMPUTED_VALUE"""),0.0) -> 0 | AD4: =IFERROR(__xludf.DUMMYFUNCTION("""COMPUTED_VALUE"""),0.732777777777777) -> 0.73277778 | AE4: =IFERROR(__xludf.DUMMYFUNCTION("""COMPUTED_VALUE"""),1.28138888888888) -> 1.2813889 | AF4: =IFERROR(__xludf.DUMMYFUNCTION("""COMPUTED_VALUE"""),0.0) -> 0
A5: =IFERROR(__xludf.DUMMYFUNCTION("""COMPUTED_VALUE"""),46153.0) -> 46153 | B5: =IFERROR(__xludf.DUMMYFUNCTION("""COMPUTED_VALUE"""),"394d109f7b50d9a46fb591dbaaba2d0aac90a696") -> 394d109f7b50d9a46fb591dbaaba2d0aac90a696 | C5: =IFERROR(__xludf.DUMMYFUNCTION("""COMPUTED_VALUE"""),"Empire of Hidden King (SRGJ) - Production Show_id") -> Empire of Hidden King (SRGJ) - Production Show_id | D5: =IFERROR(__xludf.DUMMYFUNCTION("""COMPUTED_VALUE"""),0.0) -> 0 | E5: =IFERROR(__xludf.DUMMYFUNCTION("""COMPUTED_VALUE"""),0.0) -> 0 | F5: =IFERROR(__xludf.DUMMYFUNCTION("""COMPUTED_VALUE"""),0.0) -> 0 | G5: =IFERROR(__xludf.DUMMYFUNCTION("""COMPUTED_VALUE"""),0.0) -> 0 | H5: =IFERROR(__xludf.DUMMYFUNCTION("""COMPUTED_VALUE"""),0.0) -> 0 | I5: =IFERROR(__xludf.DUMMYFUNCTION("""COMPUTED_VALUE"""),0.0) -> 0 | J5: =IFERROR(__xludf.DUMMYFUNCTION("""COMPUTED_VALUE"""),0.0) -> 0 | K5: =IFERROR(__xludf.DUMMYFUNCTION("""COMPUTED_VALUE"""),0.0) -> 0 | ... M5: =IFERROR(__xludf.DUMMYFUNCTION("""COMPUTED_VALUE"""),0.0) -> 0 | N5: =IFERROR(__xludf.DUMMYFUNCTION("""COMPUTED_VALUE"""),1.0) -> 1 | O5: =IFERROR(__xludf.DUMMYFUNCTION("""COMPUTED_VALUE"""),1.0) -> 1 | P5: =IFERROR(__xludf.DUMMYFUNCTION("""COMPUTED_VALUE"""),1.0) -> 1 | Q5: =IFERROR(__xludf.DUMMYFUNCTION("""COMPUTED_VALUE"""),0.0) -> 0 | R5: =IFERROR(__xludf.DUMMYFUNCTION("""COMPUTED_VALUE"""),0.0) -> 0 | S5: =IFERROR(__xludf.DUMMYFUNCTION("""COMPUTED_VALUE"""),0.0) -> 0 | T5: =IFERROR(__xludf.DUMMYFUNCTION("""COMPUTED_VALUE"""),0.0) -> 0 | U5: =IFERROR(__xludf.DUMMYFUNCTION("""COMPUTED_VALUE"""),0.0) -> 0 | V5: =IFERROR(__xludf.DUMMYFUNCTION("""COMPUTED_VALUE"""),0.0) -> 0 | W5: =IFERROR(__xludf.DUMMYFUNCTION("""COMPUTED_VALUE"""),0.0) -> 0 | X5: =IFERROR(__xludf.DUMMYFUNCTION("""COMPUTED_VALUE"""),0.0) -> 0 | ... AB5: =IFERROR(__xludf.DUMMYFUNCTION("""COMPUTED_VALUE"""),0.0) -> 0 | AC5: =IFERROR(__xludf.DUMMYFUNCTION("""COMPUTED_VALUE"""),0.274722222222222) -> 0.27472222 | AD5: =IFERROR(__xludf.DUMMYFUNCTION("""COMPUTED_VALUE"""),0.272222222222222) -> 0.27222222 | AE5: =IFERROR(__xludf.DUMMYFUNCTION("""COMPUTED_VALUE"""),0.274722222222222) -> 0.27472222 | AF5: =IFERROR(__xludf.DUMMYFUNCTION("""COMPUTED_VALUE"""),0.0) -> 0
A6: =IFERROR(__xludf.DUMMYFUNCTION("""COMPUTED_VALUE"""),46153.0) -> 46153 | B6: =IFERROR(__xludf.DUMMYFUNCTION("""COMPUTED_VALUE"""),"5066c0736f9e9444f2b4da840d6860b1f7f47d11") -> 5066c0736f9e9444f2b4da840d6860b1f7f47d11 | C6: =IFERROR(__xludf.DUMMYFUNCTION("""COMPUTED_VALUE"""),"The Warrior | Author - Dayaram Prajapati - Replica (For Production Only)") -> The Warrior | Author - Dayaram Prajapati - Replica (For Production Only) | D6: =IFERROR(__xludf.DUMMYFUNCTION("""COMPUTED_VALUE"""),1.0) -> 1 | E6: =IFERROR(__xludf.DUMMYFUNCTION("""COMPUTED_VALUE"""),17.0) -> 17 | F6: =IFERROR(__xludf.DUMMYFUNCTION("""COMPUTED_VALUE"""),15.0) -> 15 | G6: =IFERROR(__xludf.DUMMYFUNCTION("""COMPUTED_VALUE"""),11.0) -> 11 | H6: =IFERROR(__xludf.DUMMYFUNCTION("""COMPUTED_VALUE"""),11.0) -> 11 | I6: =IFERROR(__xludf.DUMMYFUNCTION("""COMPUTED_VALUE"""),0.0) -> 0 | J6: =IFERROR(__xludf.DUMMYFUNCTION("""COMPUTED_VALUE"""),11.0) -> 11 | K6: =IFERROR(__xludf.DUMMYFUNCTION("""COMPUTED_VALUE"""),0.0) -> 0 | L6: =IFERROR(__xludf.DUMMYFUNCTION("""COMPUTED_VALUE"""),0.0) -> 0 | M6: =IFERROR(__xludf.DUMMYFUNCTION("""COMPUTED_VALUE"""),7.0) -> 7 | N6: =IFERROR(__xludf.DUMMYFUNCTION("""COMPUTED_VALUE"""),10.0) -> 10 | O6: =IFERROR(__xludf.DUMMYFUNCTION("""COMPUTED_VALUE"""),3.0) -> 3 | P6: =IFERROR(__xludf.DUMMYFUNCTION("""COMPUTED_VALUE"""),10.0) -> 10 | Q6: =IFERROR(__xludf.DUMMYFUNCTION("""COMPUTED_VALUE"""),0.0) -> 0 | R6: =IFERROR(__xludf.DUMMYFUNCTION("""COMPUTED_VALUE"""),3118.0) -> 3118 | S6: =IFERROR(__xludf.DUMMYFUNCTION("""COMPUTED_VALUE"""),51999.0) -> 51999 | T6: =IFERROR(__xludf.DUMMYFUNCTION("""COMPUTED_VALUE"""),4.46611111111111) -> 4.4661111 | U6: =IFERROR(__xludf.DUMMYFUNCTION("""COMPUTED_VALUE"""),5.07111111111111) -> 5.0711111 | V6: =IFERROR(__xludf.DUMMYFUNCTION("""COMPUTED_VALUE"""),3.66888888888888) -> 3.6688889 | W6: =IFERROR(__xludf.DUMMYFUNCTION("""COMPUTED_VALUE"""),3.66888888888888) -> 3.6688889 | X6: =IFERROR(__xludf.DUMMYFUNCTION("""COMPUTED_VALUE"""),0.0) -> 0 | Y6: =IFERROR(__xludf.DUMMYFUNCTION("""COMPUTED_VALUE"""),3.65055555555555) -> 3.6505556 | Z6: =IFERROR(__xludf.DUMMYFUNCTION("""COMPUTED_VALUE"""),0.0) -> 0 | AA6: =IFERROR(__xludf.DUMMYFUNCTION("""COMPUTED_VALUE"""),0.0) -> 0 | AB6: =IFERROR(__xludf.DUMMYFUNCTION("""COMPUTED_VALUE"""),2.40722222222222) -> 2.4072222 | AC6: =IFERROR(__xludf.DUMMYFUNCTION("""COMPUTED_VALUE"""),3.31111111111111) -> 3.3111111 | AD6: =IFERROR(__xludf.DUMMYFUNCTION("""COMPUTED_VALUE"""),0.674999999999999) -> 0.675 | AE6: =IFERROR(__xludf.DUMMYFUNCTION("""COMPUTED_VALUE"""),3.31111111111111) -> 3.3111111 | AF6: =IFERROR(__xludf.DUMMYFUNCTION("""COMPUTED_VALUE"""),13.0) -> 13
A7: =IFERROR(__xludf.DUMMYFUNCTION("""COMPUTED_VALUE"""),46153.0) -> 46153 | B7: =IFERROR(__xludf.DUMMYFUNCTION("""COMPUTED_VALUE"""),"54847eda0794e861da74c1034ace021b4643357b") -> 54847eda0794e861da74c1034ace021b4643357b | C7: =IFERROR(__xludf.DUMMYFUNCTION("""COMPUTED_VALUE"""),"Billionaire King's Love (Production)") -> Billionaire King's Love (Production) | D7: =IFERROR(__xludf.DUMMYFUNCTION("""COMPUTED_VALUE"""),7.0) -> 7 | E7: =IFERROR(__xludf.DUMMYFUNCTION("""COMPUTED_VALUE"""),5.0) -> 5 | F7: =IFERROR(__xludf.DUMMYFUNCTION("""COMPUTED_VALUE"""),0.0) -> 0 | G7: =IFERROR(__xludf.DUMMYFUNCTION("""COMPUTED_VALUE"""),0.0) -> 0 | H7: =IFERROR(__xludf.DUMMYFUNCTION("""COMPUTED_VALUE"""),0.0) -> 0 | I7: =IFERROR(__xludf.DUMMYFUNCTION("""COMPUTED_VALUE"""),0.0) -> 0 | J7: =IFERROR(__xludf.DUMMYFUNCTION("""COMPUTED_VALUE"""),0.0) -> 0 | K7: =IFERROR(__xludf.DUMMYFUNCTION("""COMPUTED_VALUE"""),0.0) -> 0 | L7: =IFERROR(__xludf.DUMMYFUNCTION("""COMPUTED_VALUE"""),0.0) -> 0 | M7: =IFERROR(__xludf.DUMMYFUNCTION("""COMPUTED_VALUE"""),0.0) -> 0 | N7: =IFERROR(__xludf.DUMMYFUNCTION("""COMPUTED_VALUE"""),0.0) -> 0 | O7: =IFERROR(__xludf.DUMMYFUNCTION("""COMPUTED_VALUE"""),2.0) -> 2 | P7: =IFERROR(__xludf.DUMMYFUNCTION("""COMPUTED_VALUE"""),0.0) -> 0 | Q7: =IFERROR(__xludf.DUMMYFUNCTION("""COMPUTED_VALUE"""),0.0) -> 0 | R7: =IFERROR(__xludf.DUMMYFUNCTION("""COMPUTED_VALUE"""),14999.0) -> 14999 | S7: =IFERROR(__xludf.DUMMYFUNCTION("""COMPUTED_VALUE"""),12488.0) -> 12488 | T7: =IFERROR(__xludf.DUMMYFUNCTION("""COMPUTED_VALUE"""),0.0) -> 0 | U7: =IFERROR(__xludf.DUMMYFUNCTION("""COMPUTED_VALUE"""),0.0) -> 0 | V7: =IFERROR(__xludf.DUMMYFUNCTION("""COMPUTED_VALUE"""),0.0) -> 0 | W7: =IFERROR(__xludf.DUMMYFUNCTION("""COMPUTED_VALUE"""),0.0) -> 0 | X7: =IFERROR(__xludf.DUMMYFUNCTION("""COMPUTED_VALUE"""),0.0) -> 0 | Y7: =IFERROR(__xludf.DUMMYFUNCTION("""COMPUTED_VALUE"""),0.0) -> 0 | Z7: =IFERROR(__xludf.DUMMYFUNCTION("""COMPUTED_VALUE"""),0.0) -> 0 | AA7: =IFERROR(__xludf.DUMMYFUNCTION("""COMPUTED_VALUE"""),0.0) -> 0 | ... AC7: =IFERROR(__xludf.DUMMYFUNCTION("""COMPUTED_VALUE"""),0.0) -> 0 | AD7: =IFERROR(__xludf.DUMMYFUNCTION("""COMPUTED_VALUE"""),0.430555555555555) -> 0.43055556 | AE7: =IFERROR(__xludf.DUMMYFUNCTION("""COMPUTED_VALUE"""),0.0) -> 0 | AF7: =IFERROR(__xludf.DUMMYFUNCTION("""COMPUTED_VALUE"""),0.0) -> 0
A8: =IFERROR(__xludf.DUMMYFUNCTION("""COMPUTED_VALUE"""),46153.0) -> 46153 | B8: =IFERROR(__xludf.DUMMYFUNCTION("""COMPUTED_VALUE"""),"5a7d21f6ad9df12be70cd9439dd850c36627991d") -> 5a7d21f6ad9df12be70cd9439dd850c36627991d | C8: =IFERROR(__xludf.DUMMYFUNCTION("""COMPUTED_VALUE"""),"Ek Stranger Se Pyar- Production Id") -> Ek Stranger Se Pyar- Production Id | D8: =IFERROR(__xludf.DUMMYFUNCTION("""COMPUTED_VALUE"""),16.0) -> 16 | E8: =IFERROR(__xludf.DUMMYFUNCTION("""COMPUTED_VALUE"""),12.0) -> 12 | F8: =IFERROR(__xludf.DUMMYFUNCTION("""COMPUTED_VALUE"""),3.0) -> 3 | G8: =IFERROR(__xludf.DUMMYFUNCTION("""COMPUTED_VALUE"""),6.0) -> 6 | H8: =IFERROR(__xludf.DUMMYFUNCTION("""COMPUTED_VALUE"""),9.0) -> 9 | I8: =IFERROR(__xludf.DUMMYFUNCTION("""COMPUTED_VALUE"""),3.0) -> 3 | J8: =IFERROR(__xludf.DUMMYFUNCTION("""COMPUTED_VALUE"""),7.0) -> 7 | K8: =IFERROR(__xludf.DUMMYFUNCTION("""COMPUTED_VALUE"""),6.0) -> 6 | L8: =IFERROR(__xludf.DUMMYFUNCTION("""COMPUTED_VALUE"""),0.0) -> 0 | M8: =IFERROR(__xludf.DUMMYFUNCTION("""COMPUTED_VALUE"""),1.0) -> 1 | N8: =IFERROR(__xludf.DUMMYFUNCTION("""COMPUTED_VALUE"""),0.0) -> 0 | O8: =IFERROR(__xludf.DUMMYFUNCTION("""COMPUTED_VALUE"""),3.0) -> 3 | P8: =IFERROR(__xludf.DUMMYFUNCTION("""COMPUTED_VALUE"""),0.0) -> 0 | Q8: =IFERROR(__xludf.DUMMYFUNCTION("""COMPUTED_VALUE"""),0.0) -> 0 | R8: =IFERROR(__xludf.DUMMYFUNCTION("""COMPUTED_VALUE"""),38447.0) -> 38447 | S8: =IFERROR(__xludf.DUMMYFUNCTION("""COMPUTED_VALUE"""),28364.0) -> 28364 | T8: =IFERROR(__xludf.DUMMYFUNCTION("""COMPUTED_VALUE"""),2.07916666666666) -> 2.0791667 | U8: =IFERROR(__xludf.DUMMYFUNCTION("""COMPUTED_VALUE"""),0.612222222222222) -> 0.61222222 | V8: =IFERROR(__xludf.DUMMYFUNCTION("""COMPUTED_VALUE"""),1.3375) -> 1.3375 | W8: =IFERROR(__xludf.DUMMYFUNCTION("""COMPUTED_VALUE"""),1.96555555555555) -> 1.9655556 | X8: =IFERROR(__xludf.DUMMYFUNCTION("""COMPUTED_VALUE"""),0.628055555555555) -> 0.62805556 | Y8: =IFERROR(__xludf.DUMMYFUNCTION("""COMPUTED_VALUE"""),1.55583333333333) -> 1.5558333 | Z8: =IFERROR(__xludf.DUMMYFUNCTION("""COMPUTED_VALUE"""),1.34305555555555) -> 1.3430556 | AA8: =IFERROR(__xludf.DUMMYFUNCTION("""COMPUTED_VALUE"""),0.0) -> 0 | AB8: =IFERROR(__xludf.DUMMYFUNCTION("""COMPUTED_VALUE"""),0.228611111111111) -> 0.22861111 | AC8: =IFERROR(__xludf.DUMMYFUNCTION("""COMPUTED_VALUE"""),0.0) -> 0 | AD8: =IFERROR(__xludf.DUMMYFUNCTION("""COMPUTED_VALUE"""),0.708055555555555) -> 0.70805556 | AE8: =IFERROR(__xludf.DUMMYFUNCTION("""COMPUTED_VALUE"""),0.0) -> 0 | AF8: =IFERROR(__xludf.DUMMYFUNCTION("""COMPUTED_VALUE"""),10.0) -> 10
A9: =IFERROR(__xludf.DUMMYFUNCTION("""COMPUTED_VALUE"""),46153.0) -> 46153 | B9: =IFERROR(__xludf.DUMMYFUNCTION("""COMPUTED_VALUE"""),"5baf4c80faf4b2d4eb9401a1d0081872e0158e89") -> 5baf4c80faf4b2d4eb9401a1d0081872e0158e89 | C9: =IFERROR(__xludf.DUMMYFUNCTION("""COMPUTED_VALUE"""),"Brahmyodha : The Destroyer - Production showId") -> Brahmyodha : The Destroyer - Production showId | D9: =IFERROR(__xludf.DUMMYFUNCTION("""COMPUTED_VALUE"""),11.0) -> 11 | E9: =IFERROR(__xludf.DUMMYFUNCTION("""COMPUTED_VALUE"""),8.0) -> 8 | F9: =IFERROR(__xludf.DUMMYFUNCTION("""COMPUTED_VALUE"""),11.0) -> 11 | G9: =IFERROR(__xludf.DUMMYFUNCTION("""COMPUTED_VALUE"""),0.0) -> 0 | H9: =IFERROR(__xludf.DUMMYFUNCTION("""COMPUTED_VALUE"""),12.0) -> 12 | I9: =IFERROR(__xludf.DUMMYFUNCTION("""COMPUTED_VALUE"""),3.0) -> 3 | J9: =IFERROR(__xludf.DUMMYFUNCTION("""COMPUTED_VALUE"""),10.0) -> 10 | K9: =IFERROR(__xludf.DUMMYFUNCTION("""COMPUTED_VALUE"""),1.0) -> 1 | L9: =IFERROR(__xludf.DUMMYFUNCTION("""COMPUTED_VALUE"""),0.0) -> 0 | M9: =IFERROR(__xludf.DUMMYFUNCTION("""COMPUTED_VALUE"""),10.0) -> 10 | N9: =IFERROR(__xludf.DUMMYFUNCTION("""COMPUTED_VALUE"""),10.0) -> 10 | O9: =IFERROR(__xludf.DUMMYFUNCTION("""COMPUTED_VALUE"""),3.0) -> 3 | P9: =IFERROR(__xludf.DUMMYFUNCTION("""COMPUTED_VALUE"""),10.0) -> 10 | Q9: =IFERROR(__xludf.DUMMYFUNCTION("""COMPUTED_VALUE"""),0.0) -> 0 | R9: =IFERROR(__xludf.DUMMYFUNCTION("""COMPUTED_VALUE"""),24161.0) -> 24161 | S9: =IFERROR(__xludf.DUMMYFUNCTION("""COMPUTED_VALUE"""),19177.0) -> 19177 | T9: =IFERROR(__xludf.DUMMYFUNCTION("""COMPUTED_VALUE"""),2.84722222222222) -> 2.8472222 | U9: =IFERROR(__xludf.DUMMYFUNCTION("""COMPUTED_VALUE"""),2.4) -> 2.4 | V9: =IFERROR(__xludf.DUMMYFUNCTION("""COMPUTED_VALUE"""),0.0) -> 0 | W9: =IFERROR(__xludf.DUMMYFUNCTION("""COMPUTED_VALUE"""),2.62777777777777) -> 2.6277778 | X9: =IFERROR(__xludf.DUMMYFUNCTION("""COMPUTED_VALUE"""),0.668333333333333) -> 0.66833333 | Y9: =IFERROR(__xludf.DUMMYFUNCTION("""COMPUTED_VALUE"""),2.17999999999999) -> 2.18 | Z9: =IFERROR(__xludf.DUMMYFUNCTION("""COMPUTED_VALUE"""),0.208611111111111) -> 0.20861111 | AA9: =IFERROR(__xludf.DUMMYFUNCTION("""COMPUTED_VALUE"""),0.0) -> 0 | AB9: =IFERROR(__xludf.DUMMYFUNCTION("""COMPUTED_VALUE"""),2.17333333333333) -> 2.1733333 | AC9: =IFERROR(__xludf.DUMMYFUNCTION("""COMPUTED_VALUE"""),2.17333333333333) -> 2.1733333 | AD9: =IFERROR(__xludf.DUMMYFUNCTION("""COMPUTED_VALUE"""),0.645277777777777) -> 0.64527778 | AE9: =IFERROR(__xludf.DUMMYFUNCTION("""COMPUTED_VALUE"""),2.17333333333333) -> 2.1733333 | AF9: =IFERROR(__xludf.DUMMYFUNCTION("""COMPUTED_VALUE"""),13.0) -> 13
A10: =IFERROR(__xludf.DUMMYFUNCTION("""COMPUTED_VALUE"""),46153.0) -> 46153 | B10: =IFERROR(__xludf.DUMMYFUNCTION("""COMPUTED_VALUE"""),"641b6f77fd211e92df35a3bcbab67e6879e19a66") -> 641b6f77fd211e92df35a3bcbab67e6879e19a66 | C10: =IFERROR(__xludf.DUMMYFUNCTION("""COMPUTED_VALUE"""),"Mahagatha | महागाथा | Author - S. Mauryavanshi") -> Mahagatha | महागाथा | Author - S. Mauryavanshi | D10: =IFERROR(__xludf.DUMMYFUNCTION("""COMPUTED_VALUE"""),53.0) -> 53 | E10: =IFERROR(__xludf.DUMMYFUNCTION("""COMPUTED_VALUE"""),53.0) -> 53 | F10: =IFERROR(__xludf.DUMMYFUNCTION("""COMPUTED_VALUE"""),0.0) -> 0 | G10: =IFERROR(__xludf.DUMMYFUNCTION("""COMPUTED_VALUE"""),0.0) -> 0 | H10: =IFERROR(__xludf.DUMMYFUNCTION("""COMPUTED_VALUE"""),0.0) -> 0 | I10: =IFERROR(__xludf.DUMMYFUNCTION("""COMPUTED_VALUE"""),0.0) -> 0 | J10: =IFERROR(__xludf.DUMMYFUNCTION("""COMPUTED_VALUE"""),0.0) -> 0 | K10: =IFERROR(__xludf.DUMMYFUNCTION("""COMPUTED_VALUE"""),0.0) -> 0 | L10: =IFERROR(__xludf.DUMMYFUNCTION("""COMPUTED_VALUE"""),0.0) -> 0 | M10: =IFERROR(__xludf.DUMMYFUNCTION("""COMPUTED_VALUE"""),0.0) -> 0 | N10: =IFERROR(__xludf.DUMMYFUNCTION("""COMPUTED_VALUE"""),53.0) -> 53 | O10: =IFERROR(__xludf.DUMMYFUNCTION("""COMPUTED_VALUE"""),2.0) -> 2 | P10: =IFERROR(__xludf.DUMMYFUNCTION("""COMPUTED_VALUE"""),53.0) -> 53 | Q10: =IFERROR(__xludf.DUMMYFUNCTION("""COMPUTED_VALUE"""),0.0) -> 0 | R10: =IFERROR(__xludf.DUMMYFUNCTION("""COMPUTED_VALUE"""),164111.0) -> 164111 | S10: =IFERROR(__xludf.DUMMYFUNCTION("""COMPUTED_VALUE"""),164111.0) -> 164111 | T10: =IFERROR(__xludf.DUMMYFUNCTION("""COMPUTED_VALUE"""),0.0) -> 0 | U10: =IFERROR(__xludf.DUMMYFUNCTION("""COMPUTED_VALUE"""),0.0) -> 0 | V10: =IFERROR(__xludf.DUMMYFUNCTION("""COMPUTED_VALUE"""),0.0) -> 0 | W10: =IFERROR(__xludf.DUMMYFUNCTION("""COMPUTED_VALUE"""),0.0) -> 0 | X10: =IFERROR(__xludf.DUMMYFUNCTION("""COMPUTED_VALUE"""),0.0) -> 0 | Y10: =IFERROR(__xludf.DUMMYFUNCTION("""COMPUTED_VALUE"""),0.0) -> 0 | Z10: =IFERROR(__xludf.DUMMYFUNCTION("""COMPUTED_VALUE"""),0.0) -> 0 | AA10: =IFERROR(__xludf.DUMMYFUNCTION("""COMPUTED_VALUE"""),0.0) -> 0 | AB10: =IFERROR(__xludf.DUMMYFUNCTION("""COMPUTED_VALUE"""),0.0) -> 0 | AC10: =IFERROR(__xludf.DUMMYFUNCTION("""COMPUTED_VALUE"""),18.5247222222222) -> 18.524722 | AD10: =IFERROR(__xludf.DUMMYFUNCTION("""COMPUTED_VALUE"""),0.437222222222222) -> 0.43722222 | AE10: =IFERROR(__xludf.DUMMYFUNCTION("""COMPUTED_VALUE"""),18.5247222222222) -> 18.524722 | AF10: =IFERROR(__xludf.DUMMYFUNCTION("""COMPUTED_VALUE"""),0.0) -> 0
A11: =IFERROR(__xludf.DUMMYFUNCTION("""COMPUTED_VALUE"""),46153.0) -> 46153 | B11: =IFERROR(__xludf.DUMMYFUNCTION("""COMPUTED_VALUE"""),"661dba879cabc615ad2774813367b442a8ba7a6c") -> 661dba879cabc615ad2774813367b442a8ba7a6c | C11: =IFERROR(__xludf.DUMMYFUNCTION("""COMPUTED_VALUE"""),"My Devil Wife -Production Id") -> My Devil Wife -Production Id | D11: =IFERROR(__xludf.DUMMYFUNCTION("""COMPUTED_VALUE"""),3.0) -> 3 | E11: =IFERROR(__xludf.DUMMYFUNCTION("""COMPUTED_VALUE"""),14.0) -> 14 | F11: =IFERROR(__xludf.DUMMYFUNCTION("""COMPUTED_VALUE"""),0.0) -> 0 | G11: =IFERROR(__xludf.DUMMYFUNCTION("""COMPUTED_VALUE"""),0.0) -> 0 | H11: =IFERROR(__xludf.DUMMYFUNCTION("""COMPUTED_VALUE"""),0.0) -> 0 | I11: =IFERROR(__xludf.DUMMYFUNCTION("""COMPUTED_VALUE"""),0.0) -> 0 | J11: =IFERROR(__xludf.DUMMYFUNCTION("""COMPUTED_VALUE"""),0.0) -> 0 | K11: =IFERROR(__xludf.DUMMYFUNCTION("""COMPUTED_VALUE"""),0.0) -> 0 | L11: =IFERROR(__xludf.DUMMYFUNCTION("""COMPUTED_VALUE"""),0.0) -> 0 | M11: =IFERROR(__xludf.DUMMYFUNCTION("""COMPUTED_VALUE"""),0.0) -> 0 | ... Q11: =IFERROR(__xludf.DUMMYFUNCTION("""COMPUTED_VALUE"""),0.0) -> 0 | R11: =IFERROR(__xludf.DUMMYFUNCTION("""COMPUTED_VALUE"""),7096.0) -> 7096 | S11: =IFERROR(__xludf.DUMMYFUNCTION("""COMPUTED_VALUE"""),29853.0) -> 29853 | T11: =IFERROR(__xludf.DUMMYFUNCTION("""COMPUTED_VALUE"""),0.0) -> 0 | U11: =IFERROR(__xludf.DUMMYFUNCTION("""COMPUTED_VALUE"""),0.0) -> 0 | V11: =IFERROR(__xludf.DUMMYFUNCTION("""COMPUTED_VALUE"""),0.0) -> 0 | W11: =IFERROR(__xludf.DUMMYFUNCTION("""COMPUTED_VALUE"""),0.0) -> 0 | X11: =IFERROR(__xludf.DUMMYFUNCTION("""COMPUTED_VALUE"""),0.0) -> 0 | Y11: =IFERROR(__xludf.DUMMYFUNCTION("""COMPUTED_VALUE"""),0.0) -> 0 | Z11: =IFERROR(__xludf.DUMMYFUNCTION("""COMPUTED_VALUE"""),0.0) -> 0 | AA11: =IFERROR(__xludf.DUMMYFUNCTION("""COMPUTED_VALUE"""),0.0) -> 0 | ... AF11: =IFERROR(__xludf.DUMMYFUNCTION("""COMPUTED_VALUE"""),0.0) -> 0
A12: =IFERROR(__xludf.DUMMYFUNCTION("""COMPUTED_VALUE"""),46153.0) -> 46153 | B12: =IFERROR(__xludf.DUMMYFUNCTION("""COMPUTED_VALUE"""),"6867922e795be5da6320ef1d28567452800209ba") -> 6867922e795be5da6320ef1d28567452800209ba | C12: =IFERROR(__xludf.DUMMYFUNCTION("""COMPUTED_VALUE"""),"The Dimension God - Production Id") -> The Dimension God - Production Id | D12: =IFERROR(__xludf.DUMMYFUNCTION("""COMPUTED_VALUE"""),30.0) -> 30 | E12: =IFERROR(__xludf.DUMMYFUNCTION("""COMPUTED_VALUE"""),4.0) -> 4 | F12: =IFERROR(__xludf.DUMMYFUNCTION("""COMPUTED_VALUE"""),0.0) -> 0 | G12: =IFERROR(__xludf.DUMMYFUNCTION("""COMPUTED_VALUE"""),0.0) -> 0 | H12: =IFERROR(__xludf.DUMMYFUNCTION("""COMPUTED_VALUE"""),0.0) -> 0 | I12: =IFERROR(__xludf.DUMMYFUNCTION("""COMPUTED_VALUE"""),0.0) -> 0 | J12: =IFERROR(__xludf.DUMMYFUNCTION("""COMPUTED_VALUE"""),0.0) -> 0 | K12: =IFERROR(__xludf.DUMMYFUNCTION("""COMPUTED_VALUE"""),0.0) -> 0 | L12: =IFERROR(__xludf.DUMMYFUNCTION("""COMPUTED_VALUE"""),0.0) -> 0 | M12: =IFERROR(__xludf.DUMMYFUNCTION("""COMPUTED_VALUE"""),4.0) -> 4 | N12: =IFERROR(__xludf.DUMMYFUNCTION("""COMPUTED_VALUE"""),3.0) -> 3 | O12: =IFERROR(__xludf.DUMMYFUNCTION("""COMPUTED_VALUE"""),3.0) -> 3 | P12: =IFERROR(__xludf.DUMMYFUNCTION("""COMPUTED_VALUE"""),3.0) -> 3 | Q12: =IFERROR(__xludf.DUMMYFUNCTION("""COMPUTED_VALUE"""),0.0) -> 0 | R12: =IFERROR(__xludf.DUMMYFUNCTION("""COMPUTED_VALUE"""),69830.0) -> 69830 | S12: =IFERROR(__xludf.DUMMYFUNCTION("""COMPUTED_VALUE"""),10052.0) -> 10052 | T12: =IFERROR(__xludf.DUMMYFUNCTION("""COMPUTED_VALUE"""),0.257222222222222) -> 0.25722222 | U12: =IFERROR(__xludf.DUMMYFUNCTION("""COMPUTED_VALUE"""),0.0) -> 0 | V12: =IFERROR(__xludf.DUMMYFUNCTION("""COMPUTED_VALUE"""),0.0) -> 0 | W12: =IFERROR(__xludf.DUMMYFUNCTION("""COMPUTED_VALUE"""),0.0) -> 0 | X12: =IFERROR(__xludf.DUMMYFUNCTION("""COMPUTED_VALUE"""),0.0) -> 0 | Y12: =IFERROR(__xludf.DUMMYFUNCTION("""COMPUTED_VALUE"""),0.0) -> 0 | Z12: =IFERROR(__xludf.DUMMYFUNCTION("""COMPUTED_VALUE"""),0.0) -> 0 | AA12: =IFERROR(__xludf.DUMMYFUNCTION("""COMPUTED_VALUE"""),0.0) -> 0 | AB12: =IFERROR(__xludf.DUMMYFUNCTION("""COMPUTED_VALUE"""),1.01638888888888) -> 1.0163889 | AC12: =IFERROR(__xludf.DUMMYFUNCTION("""COMPUTED_VALUE"""),0.766944444444444) -> 0.76694444 | AD12: =IFERROR(__xludf.DUMMYFUNCTION("""COMPUTED_VALUE"""),0.790833333333333) -> 0.79083333 | AE12: =IFERROR(__xludf.DUMMYFUNCTION("""COMPUTED_VALUE"""),0.766944444444444) -> 0.76694444 | AF12: =IFERROR(__xludf.DUMMYFUNCTION("""COMPUTED_VALUE"""),1.0) -> 1
A13: =IFERROR(__xludf.DUMMYFUNCTION("""COMPUTED_VALUE"""),46153.0) -> 46153 | B13: =IFERROR(__xludf.DUMMYFUNCTION("""COMPUTED_VALUE"""),"773d29931b435627d0ca406e1ea1425e9a1dbcb6") -> 773d29931b435627d0ca406e1ea1425e9a1dbcb6 | C13: =IFERROR(__xludf.DUMMYFUNCTION("""COMPUTED_VALUE"""),"Mahagatha - Production") -> Mahagatha - Production | D13: =IFERROR(__xludf.DUMMYFUNCTION("""COMPUTED_VALUE"""),18.0) -> 18 | E13: =IFERROR(__xludf.DUMMYFUNCTION("""COMPUTED_VALUE"""),16.0) -> 16 | F13: =IFERROR(__xludf.DUMMYFUNCTION("""COMPUTED_VALUE"""),0.0) -> 0 | G13: =IFERROR(__xludf.DUMMYFUNCTION("""COMPUTED_VALUE"""),0.0) -> 0 | H13: =IFERROR(__xludf.DUMMYFUNCTION("""COMPUTED_VALUE"""),13.0) -> 13 | I13: =IFERROR(__xludf.DUMMYFUNCTION("""COMPUTED_VALUE"""),13.0) -> 13 | J13: =IFERROR(__xludf.DUMMYFUNCTION("""COMPUTED_VALUE"""),17.0) -> 17 | K13: =IFERROR(__xludf.DUMMYFUNCTION("""COMPUTED_VALUE"""),10.0) -> 10 | L13: =IFERROR(__xludf.DUMMYFUNCTION("""COMPUTED_VALUE"""),1.0) -> 1 | M13: =IFERROR(__xludf.DUMMYFUNCTION("""COMPUTED_VALUE"""),12.0) -> 12 | N13: =IFERROR(__xludf.DUMMYFUNCTION("""COMPUTED_VALUE"""),9.0) -> 9 | O13: =IFERROR(__xludf.DUMMYFUNCTION("""COMPUTED_VALUE"""),3.0) -> 3 | P13: =IFERROR(__xludf.DUMMYFUNCTION("""COMPUTED_VALUE"""),9.0) -> 9 | Q13: =IFERROR(__xludf.DUMMYFUNCTION("""COMPUTED_VALUE"""),0.0) -> 0 | R13: =IFERROR(__xludf.DUMMYFUNCTION("""COMPUTED_VALUE"""),52058.0) -> 52058 | S13: =IFERROR(__xludf.DUMMYFUNCTION("""COMPUTED_VALUE"""),43932.0) -> 43932 | T13: =IFERROR(__xludf.DUMMYFUNCTION("""COMPUTED_VALUE"""),3.43861111111111) -> 3.4386111 | U13: =IFERROR(__xludf.DUMMYFUNCTION("""COMPUTED_VALUE"""),0.0) -> 0 | V13: =IFERROR(__xludf.DUMMYFUNCTION("""COMPUTED_VALUE"""),0.0) -> 0 | W13: =IFERROR(__xludf.DUMMYFUNCTION("""COMPUTED_VALUE"""),2.97444444444444) -> 2.9744444 | X13: =IFERROR(__xludf.DUMMYFUNCTION("""COMPUTED_VALUE"""),2.97444444444444) -> 2.9744444 | Y13: =IFERROR(__xludf.DUMMYFUNCTION("""COMPUTED_VALUE"""),3.91694444444444) -> 3.9169444 | Z13: =IFERROR(__xludf.DUMMYFUNCTION("""COMPUTED_VALUE"""),2.30583333333333) -> 2.3058333 | AA13: =IFERROR(__xludf.DUMMYFUNCTION("""COMPUTED_VALUE"""),0.24) -> 0.24 | AB13: =IFERROR(__xludf.DUMMYFUNCTION("""COMPUTED_VALUE"""),2.74833333333333) -> 2.7483333 | AC13: =IFERROR(__xludf.DUMMYFUNCTION("""COMPUTED_VALUE"""),2.08055555555555) -> 2.0805556 | AD13: =IFERROR(__xludf.DUMMYFUNCTION("""COMPUTED_VALUE"""),0.693611111111111) -> 0.69361111 | AE13: =IFERROR(__xludf.DUMMYFUNCTION("""COMPUTED_VALUE"""),2.08055555555555) -> 2.0805556 | AF13: =IFERROR(__xludf.DUMMYFUNCTION("""COMPUTED_VALUE"""),15.0) -> 15
A14: =IFERROR(__xludf.DUMMYFUNCTION("""COMPUTED_VALUE"""),46153.0) -> 46153 | B14: =IFERROR(__xludf.DUMMYFUNCTION("""COMPUTED_VALUE"""),"7ea3277f02ef13c60cfa72336d009bf7ee6c17e8") -> 7ea3277f02ef13c60cfa72336d009bf7ee6c17e8 | C14: =IFERROR(__xludf.DUMMYFUNCTION("""COMPUTED_VALUE"""),"Saaya the Dark Love - Production Show_id") -> Saaya the Dark Love - Production Show_id | D14: =IFERROR(__xludf.DUMMYFUNCTION("""COMPUTED_VALUE"""),37.0) -> 37 | E14: =IFERROR(__xludf.DUMMYFUNCTION("""COMPUTED_VALUE"""),5.0) -> 5 | F14: =IFERROR(__xludf.DUMMYFUNCTION("""COMPUTED_VALUE"""),0.0) -> 0 | G14: =IFERROR(__xludf.DUMMYFUNCTION("""COMPUTED_VALUE"""),0.0) -> 0 | H14: =IFERROR(__xludf.DUMMYFUNCTION("""COMPUTED_VALUE"""),10.0) -> 10 | I14: =IFERROR(__xludf.DUMMYFUNCTION("""COMPUTED_VALUE"""),10.0) -> 10 | J14: =IFERROR(__xludf.DUMMYFUNCTION("""COMPUTED_VALUE"""),9.0) -> 9 | K14: =IFERROR(__xludf.DUMMYFUNCTION("""COMPUTED_VALUE"""),5.0) -> 5 | L14: =IFERROR(__xludf.DUMMYFUNCTION("""COMPUTED_VALUE"""),0.0) -> 0 | M14: =IFERROR(__xludf.DUMMYFUNCTION("""COMPUTED_VALUE"""),2.0) -> 2 | N14: =IFERROR(__xludf.DUMMYFUNCTION("""COMPUTED_VALUE"""),0.0) -> 0 | O14: =IFERROR(__xludf.DUMMYFUNCTION("""COMPUTED_VALUE"""),3.0) -> 3 | P14: =IFERROR(__xludf.DUMMYFUNCTION("""COMPUTED_VALUE"""),0.0) -> 0 | Q14: =IFERROR(__xludf.DUMMYFUNCTION("""COMPUTED_VALUE"""),0.0) -> 0 | R14: =IFERROR(__xludf.DUMMYFUNCTION("""COMPUTED_VALUE"""),75556.0) -> 75556 | S14: =IFERROR(__xludf.DUMMYFUNCTION("""COMPUTED_VALUE"""),10818.0) -> 10818 | T14: =IFERROR(__xludf.DUMMYFUNCTION("""COMPUTED_VALUE"""),0.820277777777777) -> 0.82027778 | U14: =IFERROR(__xludf.DUMMYFUNCTION("""COMPUTED_VALUE"""),0.0) -> 0 | V14: =IFERROR(__xludf.DUMMYFUNCTION("""COMPUTED_VALUE"""),0.0) -> 0 | W14: =IFERROR(__xludf.DUMMYFUNCTION("""COMPUTED_VALUE"""),2.0825) -> 2.0825 | X14: =IFERROR(__xludf.DUMMYFUNCTION("""COMPUTED_VALUE"""),2.0825) -> 2.0825 | Y14: =IFERROR(__xludf.DUMMYFUNCTION("""COMPUTED_VALUE"""),1.88055555555555) -> 1.8805556 | Z14: =IFERROR(__xludf.DUMMYFUNCTION("""COMPUTED_VALUE"""),1.0625) -> 1.0625 | AA14: =IFERROR(__xludf.DUMMYFUNCTION("""COMPUTED_VALUE"""),0.0) -> 0 | AB14: =IFERROR(__xludf.DUMMYFUNCTION("""COMPUTED_VALUE"""),0.385277777777777) -> 0.38527778 | AC14: =IFERROR(__xludf.DUMMYFUNCTION("""COMPUTED_VALUE"""),0.0) -> 0 | AD14: =IFERROR(__xludf.DUMMYFUNCTION("""COMPUTED_VALUE"""),0.718888888888888) -> 0.71888889 | AE14: =IFERROR(__xludf.DUMMYFUNCTION("""COMPUTED_VALUE"""),0.0) -> 0 | AF14: =IFERROR(__xludf.DUMMYFUNCTION("""COMPUTED_VALUE"""),4.0) -> 4
A15: =IFERROR(__xludf.DUMMYFUNCTION("""COMPUTED_VALUE"""),46153.0) -> 46153 | B15: =IFERROR(__xludf.DUMMYFUNCTION("""COMPUTED_VALUE"""),"859785ba4869b28dddcfcb0e75295d1e1ad9b5a9") -> 859785ba4869b28dddcfcb0e75295d1e1ad9b5a9 | C15: =IFERROR(__xludf.DUMMYFUNCTION("""COMPUTED_VALUE"""),"King of Dragon | किंग ऑफ ड्रैगन | Author - Nitesh") -> King of Dragon | किंग ऑफ ड्रैगन | Author - Nitesh | D15: =IFERROR(__xludf.DUMMYFUNCTION("""COMPUTED_VALUE"""),0.0) -> 0 | E15: =IFERROR(__xludf.DUMMYFUNCTION("""COMPUTED_VALUE"""),0.0) -> 0 | F15: =IFERROR(__xludf.DUMMYFUNCTION("""COMPUTED_VALUE"""),0.0) -> 0 | G15: =IFERROR(__xludf.DUMMYFUNCTION("""COMPUTED_VALUE"""),0.0) -> 0 | H15: =IFERROR(__xludf.DUMMYFUNCTION("""COMPUTED_VALUE"""),0.0) -> 0 | I15: =IFERROR(__xludf.DUMMYFUNCTION("""COMPUTED_VALUE"""),0.0) -> 0 | J15: =IFERROR(__xludf.DUMMYFUNCTION("""COMPUTED_VALUE"""),0.0) -> 0 | K15: =IFERROR(__xludf.DUMMYFUNCTION("""COMPUTED_VALUE"""),0.0) -> 0 | ... O15: =IFERROR(__xludf.DUMMYFUNCTION("""COMPUTED_VALUE"""),0.0) -> 0 | P15: =IFERROR(__xludf.DUMMYFUNCTION("""COMPUTED_VALUE"""),6.0) -> 6 | Q15: =IFERROR(__xludf.DUMMYFUNCTION("""COMPUTED_VALUE"""),0.0) -> 0 | R15: =IFERROR(__xludf.DUMMYFUNCTION("""COMPUTED_VALUE"""),0.0) -> 0 | S15: =IFERROR(__xludf.DUMMYFUNCTION("""COMPUTED_VALUE"""),0.0) -> 0 | T15: =IFERROR(__xludf.DUMMYFUNCTION("""COMPUTED_VALUE"""),0.0) -> 0 | U15: =IFERROR(__xludf.DUMMYFUNCTION("""COMPUTED_VALUE"""),0.0) -> 0 | V15: =IFERROR(__xludf.DUMMYFUNCTION("""COMPUTED_VALUE"""),0.0) -> 0 | W15: =IFERROR(__xludf.DUMMYFUNCTION("""COMPUTED_VALUE"""),0.0) -> 0 | X15: =IFERROR(__xludf.DUMMYFUNCTION("""COMPUTED_VALUE"""),0.0) -> 0 | ... AD15: =IFERROR(__xludf.DUMMYFUNCTION("""COMPUTED_VALUE"""),0.0) -> 0 | AE15: =IFERROR(__xludf.DUMMYFUNCTION("""COMPUTED_VALUE"""),1.62027777777777) -> 1.6202778 | AF15: =IFERROR(__xludf.DUMMYFUNCTION("""COMPUTED_VALUE"""),0.0) -> 0
A16: =IFERROR(__xludf.DUMMYFUNCTION("""COMPUTED_VALUE"""),46153.0) -> 46153 | B16: =IFERROR(__xludf.DUMMYFUNCTION("""COMPUTED_VALUE"""),"96f1f89e4494e06fb7f9e3c4645563fa62ef9320") -> 96f1f89e4494e06fb7f9e3c4645563fa62ef9320 | C16: =IFERROR(__xludf.DUMMYFUNCTION("""COMPUTED_VALUE"""),"King of Dragon - Production Show_id") -> King of Dragon - Production Show_id | D16: =IFERROR(__xludf.DUMMYFUNCTION("""COMPUTED_VALUE"""),10.0) -> 10 | E16: =IFERROR(__xludf.DUMMYFUNCTION("""COMPUTED_VALUE"""),8.0) -> 8 | F16: =IFERROR(__xludf.DUMMYFUNCTION("""COMPUTED_VALUE"""),8.0) -> 8 | G16: =IFERROR(__xludf.DUMMYFUNCTION("""COMPUTED_VALUE"""),10.0) -> 10 | H16: =IFERROR(__xludf.DUMMYFUNCTION("""COMPUTED_VALUE"""),10.0) -> 10 | I16: =IFERROR(__xludf.DUMMYFUNCTION("""COMPUTED_VALUE"""),0.0) -> 0 | J16: =IFERROR(__xludf.DUMMYFUNCTION("""COMPUTED_VALUE"""),10.0) -> 10 | K16: =IFERROR(__xludf.DUMMYFUNCTION("""COMPUTED_VALUE"""),2.0) -> 2 | L16: =IFERROR(__xludf.DUMMYFUNCTION("""COMPUTED_VALUE"""),1.0) -> 1 | M16: =IFERROR(__xludf.DUMMYFUNCTION("""COMPUTED_VALUE"""),10.0) -> 10 | N16: =IFERROR(__xludf.DUMMYFUNCTION("""COMPUTED_VALUE"""),4.0) -> 4 | O16: =IFERROR(__xludf.DUMMYFUNCTION("""COMPUTED_VALUE"""),3.0) -> 3 | P16: =IFERROR(__xludf.DUMMYFUNCTION("""COMPUTED_VALUE"""),4.0) -> 4 | Q16: =IFERROR(__xludf.DUMMYFUNCTION("""COMPUTED_VALUE"""),0.0) -> 0 | R16: =IFERROR(__xludf.DUMMYFUNCTION("""COMPUTED_VALUE"""),24505.0) -> 24505 | S16: =IFERROR(__xludf.DUMMYFUNCTION("""COMPUTED_VALUE"""),19251.0) -> 19251 | T16: =IFERROR(__xludf.DUMMYFUNCTION("""COMPUTED_VALUE"""),2.56805555555555) -> 2.5680556 | U16: =IFERROR(__xludf.DUMMYFUNCTION("""COMPUTED_VALUE"""),2.12944444444444) -> 2.1294444 | V16: =IFERROR(__xludf.DUMMYFUNCTION("""COMPUTED_VALUE"""),2.62416666666666) -> 2.6241667 | W16: =IFERROR(__xludf.DUMMYFUNCTION("""COMPUTED_VALUE"""),2.62416666666666) -> 2.6241667 | X16: =IFERROR(__xludf.DUMMYFUNCTION("""COMPUTED_VALUE"""),0.0) -> 0 | Y16: =IFERROR(__xludf.DUMMYFUNCTION("""COMPUTED_VALUE"""),2.62416666666666) -> 2.6241667 | Z16: =IFERROR(__xludf.DUMMYFUNCTION("""COMPUTED_VALUE"""),0.486666666666666) -> 0.48666667 | AA16: =IFERROR(__xludf.DUMMYFUNCTION("""COMPUTED_VALUE"""),0.246666666666666) -> 0.24666667 | AB16: =IFERROR(__xludf.DUMMYFUNCTION("""COMPUTED_VALUE"""),2.62416666666666) -> 2.6241667 | AC16: =IFERROR(__xludf.DUMMYFUNCTION("""COMPUTED_VALUE"""),1.04388888888888) -> 1.0438889 | AD16: =IFERROR(__xludf.DUMMYFUNCTION("""COMPUTED_VALUE"""),0.911944444444444) -> 0.91194444 | AE16: =IFERROR(__xludf.DUMMYFUNCTION("""COMPUTED_VALUE"""),1.04388888888888) -> 1.0438889 | AF16: =IFERROR(__xludf.DUMMYFUNCTION("""COMPUTED_VALUE"""),10.0) -> 10
